2021-06-28 03:16:08,172 ERROR HTTPConnectionPool(host='oj-backend', port=8000): Max retries exceeded with url: /api/judge_server_heartbeat/ (Caused by NewConnectionError('<urllib3.connection.HTTPConnection object at 0x7fe4fac4aa58>: Failed to establish a new connection: [Errno 111] Connection refused',))
Traceback (most recent call last):
  File "/usr/local/lib/python3.6/dist-packages/urllib3/connection.py", line 160, in _new_conn
    (self._dns_host, self.port), self.timeout, **extra_kw
  File "/usr/local/lib/python3.6/dist-packages/urllib3/util/connection.py", line 84, in create_connection
    raise err
  File "/usr/local/lib/python3.6/dist-packages/urllib3/util/connection.py", line 74, in create_connection
    sock.connect(sa)
ConnectionRefusedError: [Errno 111] Connection refused

During handling of the above exception, another exception occurred:

Traceback (most recent call last):
  File "/usr/local/lib/python3.6/dist-packages/urllib3/connectionpool.py", line 677, in urlopen
    chunked=chunked,
  File "/usr/local/lib/python3.6/dist-packages/urllib3/connectionpool.py", line 392, in _make_request
    conn.request(method, url, **httplib_request_kw)
  File "/usr/lib/python3.6/http/client.py", line 1264, in request
    self._send_request(method, url, body, headers, encode_chunked)
  File "/usr/lib/python3.6/http/client.py", line 1310, in _send_request
    self.endheaders(body, encode_chunked=encode_chunked)
  File "/usr/lib/python3.6/http/client.py", line 1259, in endheaders
    self._send_output(message_body, encode_chunked=encode_chunked)
  File "/usr/lib/python3.6/http/client.py", line 1038, in _send_output
    self.send(msg)
  File "/usr/lib/python3.6/http/client.py", line 976, in send
    self.connect()
  File "/usr/local/lib/python3.6/dist-packages/urllib3/connection.py", line 187, in connect
    conn = self._new_conn()
  File "/usr/local/lib/python3.6/dist-packages/urllib3/connection.py", line 172, in _new_conn
    self, "Failed to establish a new connection: %s" % e
urllib3.exceptions.NewConnectionError: <urllib3.connection.HTTPConnection object at 0x7fe4fac4aa58>: Failed to establish a new connection: [Errno 111] Connection refused

During handling of the above exception, another exception occurred:

Traceback (most recent call last):
  File "/usr/local/lib/python3.6/dist-packages/requests/adapters.py", line 449, in send
    timeout=timeout
  File "/usr/local/lib/python3.6/dist-packages/urllib3/connectionpool.py", line 725, in urlopen
    method, url, error=e, _pool=self, _stacktrace=sys.exc_info()[2]
  File "/usr/local/lib/python3.6/dist-packages/urllib3/util/retry.py", line 439, in increment
    raise MaxRetryError(_pool, url, error or ResponseError(cause))
urllib3.exceptions.MaxRetryError: HTTPConnectionPool(host='oj-backend', port=8000): Max retries exceeded with url: /api/judge_server_heartbeat/ (Caused by NewConnectionError('<urllib3.connection.HTTPConnection object at 0x7fe4fac4aa58>: Failed to establish a new connection: [Errno 111] Connection refused',))

During handling of the above exception, another exception occurred:

Traceback (most recent call last):
  File "/code/service.py", line 19, in _request
    "Content-Type": "application/json"}, timeout=5).text
  File "/usr/local/lib/python3.6/dist-packages/requests/api.py", line 119, in post
    return request('post', url, data=data, json=json, **kwargs)
  File "/usr/local/lib/python3.6/dist-packages/requests/api.py", line 61, in request
    return session.request(method=method, url=url, **kwargs)
  File "/usr/local/lib/python3.6/dist-packages/requests/sessions.py", line 530, in request
    resp = self.send(prep, **send_kwargs)
  File "/usr/local/lib/python3.6/dist-packages/requests/sessions.py", line 643, in send
    r = adapter.send(request, **kwargs)
  File "/usr/local/lib/python3.6/dist-packages/requests/adapters.py", line 516, in send
    raise ConnectionError(e, request=request)
requests.exceptions.ConnectionError: HTTPConnectionPool(host='oj-backend', port=8000): Max retries exceeded with url: /api/judge_server_heartbeat/ (Caused by NewConnectionError('<urllib3.connection.HTTPConnection object at 0x7fe4fac4aa58>: Failed to establish a new connection: [Errno 111] Connection refused',))
2021-06-28 03:16:08,199 ERROR 
Traceback (most recent call last):
  File "/usr/local/lib/python3.6/dist-packages/urllib3/connection.py", line 160, in _new_conn
    (self._dns_host, self.port), self.timeout, **extra_kw
  File "/usr/local/lib/python3.6/dist-packages/urllib3/util/connection.py", line 84, in create_connection
    raise err
  File "/usr/local/lib/python3.6/dist-packages/urllib3/util/connection.py", line 74, in create_connection
    sock.connect(sa)
ConnectionRefusedError: [Errno 111] Connection refused

During handling of the above exception, another exception occurred:

Traceback (most recent call last):
  File "/usr/local/lib/python3.6/dist-packages/urllib3/connectionpool.py", line 677, in urlopen
    chunked=chunked,
  File "/usr/local/lib/python3.6/dist-packages/urllib3/connectionpool.py", line 392, in _make_request
    conn.request(method, url, **httplib_request_kw)
  File "/usr/lib/python3.6/http/client.py", line 1264, in request
    self._send_request(method, url, body, headers, encode_chunked)
  File "/usr/lib/python3.6/http/client.py", line 1310, in _send_request
    self.endheaders(body, encode_chunked=encode_chunked)
  File "/usr/lib/python3.6/http/client.py", line 1259, in endheaders
    self._send_output(message_body, encode_chunked=encode_chunked)
  File "/usr/lib/python3.6/http/client.py", line 1038, in _send_output
    self.send(msg)
  File "/usr/lib/python3.6/http/client.py", line 976, in send
    self.connect()
  File "/usr/local/lib/python3.6/dist-packages/urllib3/connection.py", line 187, in connect
    conn = self._new_conn()
  File "/usr/local/lib/python3.6/dist-packages/urllib3/connection.py", line 172, in _new_conn
    self, "Failed to establish a new connection: %s" % e
urllib3.exceptions.NewConnectionError: <urllib3.connection.HTTPConnection object at 0x7fe4fac4aa58>: Failed to establish a new connection: [Errno 111] Connection refused

During handling of the above exception, another exception occurred:

Traceback (most recent call last):
  File "/usr/local/lib/python3.6/dist-packages/requests/adapters.py", line 449, in send
    timeout=timeout
  File "/usr/local/lib/python3.6/dist-packages/urllib3/connectionpool.py", line 725, in urlopen
    method, url, error=e, _pool=self, _stacktrace=sys.exc_info()[2]
  File "/usr/local/lib/python3.6/dist-packages/urllib3/util/retry.py", line 439, in increment
    raise MaxRetryError(_pool, url, error or ResponseError(cause))
urllib3.exceptions.MaxRetryError: HTTPConnectionPool(host='oj-backend', port=8000): Max retries exceeded with url: /api/judge_server_heartbeat/ (Caused by NewConnectionError('<urllib3.connection.HTTPConnection object at 0x7fe4fac4aa58>: Failed to establish a new connection: [Errno 111] Connection refused',))

During handling of the above exception, another exception occurred:

Traceback (most recent call last):
  File "/code/service.py", line 19, in _request
    "Content-Type": "application/json"}, timeout=5).text
  File "/usr/local/lib/python3.6/dist-packages/requests/api.py", line 119, in post
    return request('post', url, data=data, json=json, **kwargs)
  File "/usr/local/lib/python3.6/dist-packages/requests/api.py", line 61, in request
    return session.request(method=method, url=url, **kwargs)
  File "/usr/local/lib/python3.6/dist-packages/requests/sessions.py", line 530, in request
    resp = self.send(prep, **send_kwargs)
  File "/usr/local/lib/python3.6/dist-packages/requests/sessions.py", line 643, in send
    r = adapter.send(request, **kwargs)
  File "/usr/local/lib/python3.6/dist-packages/requests/adapters.py", line 516, in send
    raise ConnectionError(e, request=request)
requests.exceptions.ConnectionError: HTTPConnectionPool(host='oj-backend', port=8000): Max retries exceeded with url: /api/judge_server_heartbeat/ (Caused by NewConnectionError('<urllib3.connection.HTTPConnection object at 0x7fe4fac4aa58>: Failed to establish a new connection: [Errno 111] Connection refused',))

During handling of the above exception, another exception occurred:

Traceback (most recent call last):
  File "/code/service.py", line 42, in <module>
    service.heartbeat()
  File "/code/service.py", line 35, in heartbeat
    self._request(data)
  File "/code/service.py", line 22, in _request
    raise JudgeServiceError("Heartbeat request failed")
exception.JudgeServiceError
2021-06-28 03:16:13,785 ERROR HTTPConnectionPool(host='oj-backend', port=8000): Max retries exceeded with url: /api/judge_server_heartbeat/ (Caused by NewConnectionError('<urllib3.connection.HTTPConnection object at 0x7fe1b1a4b9e8>: Failed to establish a new connection: [Errno 111] Connection refused',))
Traceback (most recent call last):
  File "/usr/local/lib/python3.6/dist-packages/urllib3/connection.py", line 160, in _new_conn
    (self._dns_host, self.port), self.timeout, **extra_kw
  File "/usr/local/lib/python3.6/dist-packages/urllib3/util/connection.py", line 84, in create_connection
    raise err
  File "/usr/local/lib/python3.6/dist-packages/urllib3/util/connection.py", line 74, in create_connection
    sock.connect(sa)
ConnectionRefusedError: [Errno 111] Connection refused

During handling of the above exception, another exception occurred:

Traceback (most recent call last):
  File "/usr/local/lib/python3.6/dist-packages/urllib3/connectionpool.py", line 677, in urlopen
    chunked=chunked,
  File "/usr/local/lib/python3.6/dist-packages/urllib3/connectionpool.py", line 392, in _make_request
    conn.request(method, url, **httplib_request_kw)
  File "/usr/lib/python3.6/http/client.py", line 1264, in request
    self._send_request(method, url, body, headers, encode_chunked)
  File "/usr/lib/python3.6/http/client.py", line 1310, in _send_request
    self.endheaders(body, encode_chunked=encode_chunked)
  File "/usr/lib/python3.6/http/client.py", line 1259, in endheaders
    self._send_output(message_body, encode_chunked=encode_chunked)
  File "/usr/lib/python3.6/http/client.py", line 1038, in _send_output
    self.send(msg)
  File "/usr/lib/python3.6/http/client.py", line 976, in send
    self.connect()
  File "/usr/local/lib/python3.6/dist-packages/urllib3/connection.py", line 187, in connect
    conn = self._new_conn()
  File "/usr/local/lib/python3.6/dist-packages/urllib3/connection.py", line 172, in _new_conn
    self, "Failed to establish a new connection: %s" % e
urllib3.exceptions.NewConnectionError: <urllib3.connection.HTTPConnection object at 0x7fe1b1a4b9e8>: Failed to establish a new connection: [Errno 111] Connection refused

During handling of the above exception, another exception occurred:

Traceback (most recent call last):
  File "/usr/local/lib/python3.6/dist-packages/requests/adapters.py", line 449, in send
    timeout=timeout
  File "/usr/local/lib/python3.6/dist-packages/urllib3/connectionpool.py", line 725, in urlopen
    method, url, error=e, _pool=self, _stacktrace=sys.exc_info()[2]
  File "/usr/local/lib/python3.6/dist-packages/urllib3/util/retry.py", line 439, in increment
    raise MaxRetryError(_pool, url, error or ResponseError(cause))
urllib3.exceptions.MaxRetryError: HTTPConnectionPool(host='oj-backend', port=8000): Max retries exceeded with url: /api/judge_server_heartbeat/ (Caused by NewConnectionError('<urllib3.connection.HTTPConnection object at 0x7fe1b1a4b9e8>: Failed to establish a new connection: [Errno 111] Connection refused',))

During handling of the above exception, another exception occurred:

Traceback (most recent call last):
  File "/code/service.py", line 19, in _request
    "Content-Type": "application/json"}, timeout=5).text
  File "/usr/local/lib/python3.6/dist-packages/requests/api.py", line 119, in post
    return request('post', url, data=data, json=json, **kwargs)
  File "/usr/local/lib/python3.6/dist-packages/requests/api.py", line 61, in request
    return session.request(method=method, url=url, **kwargs)
  File "/usr/local/lib/python3.6/dist-packages/requests/sessions.py", line 530, in request
    resp = self.send(prep, **send_kwargs)
  File "/usr/local/lib/python3.6/dist-packages/requests/sessions.py", line 643, in send
    r = adapter.send(request, **kwargs)
  File "/usr/local/lib/python3.6/dist-packages/requests/adapters.py", line 516, in send
    raise ConnectionError(e, request=request)
requests.exceptions.ConnectionError: HTTPConnectionPool(host='oj-backend', port=8000): Max retries exceeded with url: /api/judge_server_heartbeat/ (Caused by NewConnectionError('<urllib3.connection.HTTPConnection object at 0x7fe1b1a4b9e8>: Failed to establish a new connection: [Errno 111] Connection refused',))
2021-06-28 03:16:13,809 ERROR 
Traceback (most recent call last):
  File "/usr/local/lib/python3.6/dist-packages/urllib3/connection.py", line 160, in _new_conn
    (self._dns_host, self.port), self.timeout, **extra_kw
  File "/usr/local/lib/python3.6/dist-packages/urllib3/util/connection.py", line 84, in create_connection
    raise err
  File "/usr/local/lib/python3.6/dist-packages/urllib3/util/connection.py", line 74, in create_connection
    sock.connect(sa)
ConnectionRefusedError: [Errno 111] Connection refused

During handling of the above exception, another exception occurred:

Traceback (most recent call last):
  File "/usr/local/lib/python3.6/dist-packages/urllib3/connectionpool.py", line 677, in urlopen
    chunked=chunked,
  File "/usr/local/lib/python3.6/dist-packages/urllib3/connectionpool.py", line 392, in _make_request
    conn.request(method, url, **httplib_request_kw)
  File "/usr/lib/python3.6/http/client.py", line 1264, in request
    self._send_request(method, url, body, headers, encode_chunked)
  File "/usr/lib/python3.6/http/client.py", line 1310, in _send_request
    self.endheaders(body, encode_chunked=encode_chunked)
  File "/usr/lib/python3.6/http/client.py", line 1259, in endheaders
    self._send_output(message_body, encode_chunked=encode_chunked)
  File "/usr/lib/python3.6/http/client.py", line 1038, in _send_output
    self.send(msg)
  File "/usr/lib/python3.6/http/client.py", line 976, in send
    self.connect()
  File "/usr/local/lib/python3.6/dist-packages/urllib3/connection.py", line 187, in connect
    conn = self._new_conn()
  File "/usr/local/lib/python3.6/dist-packages/urllib3/connection.py", line 172, in _new_conn
    self, "Failed to establish a new connection: %s" % e
urllib3.exceptions.NewConnectionError: <urllib3.connection.HTTPConnection object at 0x7fe1b1a4b9e8>: Failed to establish a new connection: [Errno 111] Connection refused

During handling of the above exception, another exception occurred:

Traceback (most recent call last):
  File "/usr/local/lib/python3.6/dist-packages/requests/adapters.py", line 449, in send
    timeout=timeout
  File "/usr/local/lib/python3.6/dist-packages/urllib3/connectionpool.py", line 725, in urlopen
    method, url, error=e, _pool=self, _stacktrace=sys.exc_info()[2]
  File "/usr/local/lib/python3.6/dist-packages/urllib3/util/retry.py", line 439, in increment
    raise MaxRetryError(_pool, url, error or ResponseError(cause))
urllib3.exceptions.MaxRetryError: HTTPConnectionPool(host='oj-backend', port=8000): Max retries exceeded with url: /api/judge_server_heartbeat/ (Caused by NewConnectionError('<urllib3.connection.HTTPConnection object at 0x7fe1b1a4b9e8>: Failed to establish a new connection: [Errno 111] Connection refused',))

During handling of the above exception, another exception occurred:

Traceback (most recent call last):
  File "/code/service.py", line 19, in _request
    "Content-Type": "application/json"}, timeout=5).text
  File "/usr/local/lib/python3.6/dist-packages/requests/api.py", line 119, in post
    return request('post', url, data=data, json=json, **kwargs)
  File "/usr/local/lib/python3.6/dist-packages/requests/api.py", line 61, in request
    return session.request(method=method, url=url, **kwargs)
  File "/usr/local/lib/python3.6/dist-packages/requests/sessions.py", line 530, in request
    resp = self.send(prep, **send_kwargs)
  File "/usr/local/lib/python3.6/dist-packages/requests/sessions.py", line 643, in send
    r = adapter.send(request, **kwargs)
  File "/usr/local/lib/python3.6/dist-packages/requests/adapters.py", line 516, in send
    raise ConnectionError(e, request=request)
requests.exceptions.ConnectionError: HTTPConnectionPool(host='oj-backend', port=8000): Max retries exceeded with url: /api/judge_server_heartbeat/ (Caused by NewConnectionError('<urllib3.connection.HTTPConnection object at 0x7fe1b1a4b9e8>: Failed to establish a new connection: [Errno 111] Connection refused',))

During handling of the above exception, another exception occurred:

Traceback (most recent call last):
  File "/code/service.py", line 42, in <module>
    service.heartbeat()
  File "/code/service.py", line 35, in heartbeat
    self._request(data)
  File "/code/service.py", line 22, in _request
    raise JudgeServiceError("Heartbeat request failed")
exception.JudgeServiceError
2021-06-28 03:16:19,365 ERROR HTTPConnectionPool(host='oj-backend', port=8000): Max retries exceeded with url: /api/judge_server_heartbeat/ (Caused by NewConnectionError('<urllib3.connection.HTTPConnection object at 0x7fbb9f1a7a58>: Failed to establish a new connection: [Errno 111] Connection refused',))
Traceback (most recent call last):
  File "/usr/local/lib/python3.6/dist-packages/urllib3/connection.py", line 160, in _new_conn
    (self._dns_host, self.port), self.timeout, **extra_kw
  File "/usr/local/lib/python3.6/dist-packages/urllib3/util/connection.py", line 84, in create_connection
    raise err
  File "/usr/local/lib/python3.6/dist-packages/urllib3/util/connection.py", line 74, in create_connection
    sock.connect(sa)
ConnectionRefusedError: [Errno 111] Connection refused

During handling of the above exception, another exception occurred:

Traceback (most recent call last):
  File "/usr/local/lib/python3.6/dist-packages/urllib3/connectionpool.py", line 677, in urlopen
    chunked=chunked,
  File "/usr/local/lib/python3.6/dist-packages/urllib3/connectionpool.py", line 392, in _make_request
    conn.request(method, url, **httplib_request_kw)
  File "/usr/lib/python3.6/http/client.py", line 1264, in request
    self._send_request(method, url, body, headers, encode_chunked)
  File "/usr/lib/python3.6/http/client.py", line 1310, in _send_request
    self.endheaders(body, encode_chunked=encode_chunked)
  File "/usr/lib/python3.6/http/client.py", line 1259, in endheaders
    self._send_output(message_body, encode_chunked=encode_chunked)
  File "/usr/lib/python3.6/http/client.py", line 1038, in _send_output
    self.send(msg)
  File "/usr/lib/python3.6/http/client.py", line 976, in send
    self.connect()
  File "/usr/local/lib/python3.6/dist-packages/urllib3/connection.py", line 187, in connect
    conn = self._new_conn()
  File "/usr/local/lib/python3.6/dist-packages/urllib3/connection.py", line 172, in _new_conn
    self, "Failed to establish a new connection: %s" % e
urllib3.exceptions.NewConnectionError: <urllib3.connection.HTTPConnection object at 0x7fbb9f1a7a58>: Failed to establish a new connection: [Errno 111] Connection refused

During handling of the above exception, another exception occurred:

Traceback (most recent call last):
  File "/usr/local/lib/python3.6/dist-packages/requests/adapters.py", line 449, in send
    timeout=timeout
  File "/usr/local/lib/python3.6/dist-packages/urllib3/connectionpool.py", line 725, in urlopen
    method, url, error=e, _pool=self, _stacktrace=sys.exc_info()[2]
  File "/usr/local/lib/python3.6/dist-packages/urllib3/util/retry.py", line 439, in increment
    raise MaxRetryError(_pool, url, error or ResponseError(cause))
urllib3.exceptions.MaxRetryError: HTTPConnectionPool(host='oj-backend', port=8000): Max retries exceeded with url: /api/judge_server_heartbeat/ (Caused by NewConnectionError('<urllib3.connection.HTTPConnection object at 0x7fbb9f1a7a58>: Failed to establish a new connection: [Errno 111] Connection refused',))

During handling of the above exception, another exception occurred:

Traceback (most recent call last):
  File "/code/service.py", line 19, in _request
    "Content-Type": "application/json"}, timeout=5).text
  File "/usr/local/lib/python3.6/dist-packages/requests/api.py", line 119, in post
    return request('post', url, data=data, json=json, **kwargs)
  File "/usr/local/lib/python3.6/dist-packages/requests/api.py", line 61, in request
    return session.request(method=method, url=url, **kwargs)
  File "/usr/local/lib/python3.6/dist-packages/requests/sessions.py", line 530, in request
    resp = self.send(prep, **send_kwargs)
  File "/usr/local/lib/python3.6/dist-packages/requests/sessions.py", line 643, in send
    r = adapter.send(request, **kwargs)
  File "/usr/local/lib/python3.6/dist-packages/requests/adapters.py", line 516, in send
    raise ConnectionError(e, request=request)
requests.exceptions.ConnectionError: HTTPConnectionPool(host='oj-backend', port=8000): Max retries exceeded with url: /api/judge_server_heartbeat/ (Caused by NewConnectionError('<urllib3.connection.HTTPConnection object at 0x7fbb9f1a7a58>: Failed to establish a new connection: [Errno 111] Connection refused',))
2021-06-28 03:16:19,369 ERROR 
Traceback (most recent call last):
  File "/usr/local/lib/python3.6/dist-packages/urllib3/connection.py", line 160, in _new_conn
    (self._dns_host, self.port), self.timeout, **extra_kw
  File "/usr/local/lib/python3.6/dist-packages/urllib3/util/connection.py", line 84, in create_connection
    raise err
  File "/usr/local/lib/python3.6/dist-packages/urllib3/util/connection.py", line 74, in create_connection
    sock.connect(sa)
ConnectionRefusedError: [Errno 111] Connection refused

During handling of the above exception, another exception occurred:

Traceback (most recent call last):
  File "/usr/local/lib/python3.6/dist-packages/urllib3/connectionpool.py", line 677, in urlopen
    chunked=chunked,
  File "/usr/local/lib/python3.6/dist-packages/urllib3/connectionpool.py", line 392, in _make_request
    conn.request(method, url, **httplib_request_kw)
  File "/usr/lib/python3.6/http/client.py", line 1264, in request
    self._send_request(method, url, body, headers, encode_chunked)
  File "/usr/lib/python3.6/http/client.py", line 1310, in _send_request
    self.endheaders(body, encode_chunked=encode_chunked)
  File "/usr/lib/python3.6/http/client.py", line 1259, in endheaders
    self._send_output(message_body, encode_chunked=encode_chunked)
  File "/usr/lib/python3.6/http/client.py", line 1038, in _send_output
    self.send(msg)
  File "/usr/lib/python3.6/http/client.py", line 976, in send
    self.connect()
  File "/usr/local/lib/python3.6/dist-packages/urllib3/connection.py", line 187, in connect
    conn = self._new_conn()
  File "/usr/local/lib/python3.6/dist-packages/urllib3/connection.py", line 172, in _new_conn
    self, "Failed to establish a new connection: %s" % e
urllib3.exceptions.NewConnectionError: <urllib3.connection.HTTPConnection object at 0x7fbb9f1a7a58>: Failed to establish a new connection: [Errno 111] Connection refused

During handling of the above exception, another exception occurred:

Traceback (most recent call last):
  File "/usr/local/lib/python3.6/dist-packages/requests/adapters.py", line 449, in send
    timeout=timeout
  File "/usr/local/lib/python3.6/dist-packages/urllib3/connectionpool.py", line 725, in urlopen
    method, url, error=e, _pool=self, _stacktrace=sys.exc_info()[2]
  File "/usr/local/lib/python3.6/dist-packages/urllib3/util/retry.py", line 439, in increment
    raise MaxRetryError(_pool, url, error or ResponseError(cause))
urllib3.exceptions.MaxRetryError: HTTPConnectionPool(host='oj-backend', port=8000): Max retries exceeded with url: /api/judge_server_heartbeat/ (Caused by NewConnectionError('<urllib3.connection.HTTPConnection object at 0x7fbb9f1a7a58>: Failed to establish a new connection: [Errno 111] Connection refused',))

During handling of the above exception, another exception occurred:

Traceback (most recent call last):
  File "/code/service.py", line 19, in _request
    "Content-Type": "application/json"}, timeout=5).text
  File "/usr/local/lib/python3.6/dist-packages/requests/api.py", line 119, in post
    return request('post', url, data=data, json=json, **kwargs)
  File "/usr/local/lib/python3.6/dist-packages/requests/api.py", line 61, in request
    return session.request(method=method, url=url, **kwargs)
  File "/usr/local/lib/python3.6/dist-packages/requests/sessions.py", line 530, in request
    resp = self.send(prep, **send_kwargs)
  File "/usr/local/lib/python3.6/dist-packages/requests/sessions.py", line 643, in send
    r = adapter.send(request, **kwargs)
  File "/usr/local/lib/python3.6/dist-packages/requests/adapters.py", line 516, in send
    raise ConnectionError(e, request=request)
requests.exceptions.ConnectionError: HTTPConnectionPool(host='oj-backend', port=8000): Max retries exceeded with url: /api/judge_server_heartbeat/ (Caused by NewConnectionError('<urllib3.connection.HTTPConnection object at 0x7fbb9f1a7a58>: Failed to establish a new connection: [Errno 111] Connection refused',))

During handling of the above exception, another exception occurred:

Traceback (most recent call last):
  File "/code/service.py", line 42, in <module>
    service.heartbeat()
  File "/code/service.py", line 35, in heartbeat
    self._request(data)
  File "/code/service.py", line 22, in _request
    raise JudgeServiceError("Heartbeat request failed")
exception.JudgeServiceError
2021-06-28 03:16:25,436 ERROR HTTPConnectionPool(host='oj-backend', port=8000): Max retries exceeded with url: /api/judge_server_heartbeat/ (Caused by NewConnectionError('<urllib3.connection.HTTPConnection object at 0x7f4f00072a58>: Failed to establish a new connection: [Errno 111] Connection refused',))
Traceback (most recent call last):
  File "/usr/local/lib/python3.6/dist-packages/urllib3/connection.py", line 160, in _new_conn
    (self._dns_host, self.port), self.timeout, **extra_kw
  File "/usr/local/lib/python3.6/dist-packages/urllib3/util/connection.py", line 84, in create_connection
    raise err
  File "/usr/local/lib/python3.6/dist-packages/urllib3/util/connection.py", line 74, in create_connection
    sock.connect(sa)
ConnectionRefusedError: [Errno 111] Connection refused

During handling of the above exception, another exception occurred:

Traceback (most recent call last):
  File "/usr/local/lib/python3.6/dist-packages/urllib3/connectionpool.py", line 677, in urlopen
    chunked=chunked,
  File "/usr/local/lib/python3.6/dist-packages/urllib3/connectionpool.py", line 392, in _make_request
    conn.request(method, url, **httplib_request_kw)
  File "/usr/lib/python3.6/http/client.py", line 1264, in request
    self._send_request(method, url, body, headers, encode_chunked)
  File "/usr/lib/python3.6/http/client.py", line 1310, in _send_request
    self.endheaders(body, encode_chunked=encode_chunked)
  File "/usr/lib/python3.6/http/client.py", line 1259, in endheaders
    self._send_output(message_body, encode_chunked=encode_chunked)
  File "/usr/lib/python3.6/http/client.py", line 1038, in _send_output
    self.send(msg)
  File "/usr/lib/python3.6/http/client.py", line 976, in send
    self.connect()
  File "/usr/local/lib/python3.6/dist-packages/urllib3/connection.py", line 187, in connect
    conn = self._new_conn()
  File "/usr/local/lib/python3.6/dist-packages/urllib3/connection.py", line 172, in _new_conn
    self, "Failed to establish a new connection: %s" % e
urllib3.exceptions.NewConnectionError: <urllib3.connection.HTTPConnection object at 0x7f4f00072a58>: Failed to establish a new connection: [Errno 111] Connection refused

During handling of the above exception, another exception occurred:

Traceback (most recent call last):
  File "/usr/local/lib/python3.6/dist-packages/requests/adapters.py", line 449, in send
    timeout=timeout
  File "/usr/local/lib/python3.6/dist-packages/urllib3/connectionpool.py", line 725, in urlopen
    method, url, error=e, _pool=self, _stacktrace=sys.exc_info()[2]
  File "/usr/local/lib/python3.6/dist-packages/urllib3/util/retry.py", line 439, in increment
    raise MaxRetryError(_pool, url, error or ResponseError(cause))
urllib3.exceptions.MaxRetryError: HTTPConnectionPool(host='oj-backend', port=8000): Max retries exceeded with url: /api/judge_server_heartbeat/ (Caused by NewConnectionError('<urllib3.connection.HTTPConnection object at 0x7f4f00072a58>: Failed to establish a new connection: [Errno 111] Connection refused',))

During handling of the above exception, another exception occurred:

Traceback (most recent call last):
  File "/code/service.py", line 19, in _request
    "Content-Type": "application/json"}, timeout=5).text
  File "/usr/local/lib/python3.6/dist-packages/requests/api.py", line 119, in post
    return request('post', url, data=data, json=json, **kwargs)
  File "/usr/local/lib/python3.6/dist-packages/requests/api.py", line 61, in request
    return session.request(method=method, url=url, **kwargs)
  File "/usr/local/lib/python3.6/dist-packages/requests/sessions.py", line 530, in request
    resp = self.send(prep, **send_kwargs)
  File "/usr/local/lib/python3.6/dist-packages/requests/sessions.py", line 643, in send
    r = adapter.send(request, **kwargs)
  File "/usr/local/lib/python3.6/dist-packages/requests/adapters.py", line 516, in send
    raise ConnectionError(e, request=request)
requests.exceptions.ConnectionError: HTTPConnectionPool(host='oj-backend', port=8000): Max retries exceeded with url: /api/judge_server_heartbeat/ (Caused by NewConnectionError('<urllib3.connection.HTTPConnection object at 0x7f4f00072a58>: Failed to establish a new connection: [Errno 111] Connection refused',))
2021-06-28 03:16:25,446 ERROR 
Traceback (most recent call last):
  File "/usr/local/lib/python3.6/dist-packages/urllib3/connection.py", line 160, in _new_conn
    (self._dns_host, self.port), self.timeout, **extra_kw
  File "/usr/local/lib/python3.6/dist-packages/urllib3/util/connection.py", line 84, in create_connection
    raise err
  File "/usr/local/lib/python3.6/dist-packages/urllib3/util/connection.py", line 74, in create_connection
    sock.connect(sa)
ConnectionRefusedError: [Errno 111] Connection refused

During handling of the above exception, another exception occurred:

Traceback (most recent call last):
  File "/usr/local/lib/python3.6/dist-packages/urllib3/connectionpool.py", line 677, in urlopen
    chunked=chunked,
  File "/usr/local/lib/python3.6/dist-packages/urllib3/connectionpool.py", line 392, in _make_request
    conn.request(method, url, **httplib_request_kw)
  File "/usr/lib/python3.6/http/client.py", line 1264, in request
    self._send_request(method, url, body, headers, encode_chunked)
  File "/usr/lib/python3.6/http/client.py", line 1310, in _send_request
    self.endheaders(body, encode_chunked=encode_chunked)
  File "/usr/lib/python3.6/http/client.py", line 1259, in endheaders
    self._send_output(message_body, encode_chunked=encode_chunked)
  File "/usr/lib/python3.6/http/client.py", line 1038, in _send_output
    self.send(msg)
  File "/usr/lib/python3.6/http/client.py", line 976, in send
    self.connect()
  File "/usr/local/lib/python3.6/dist-packages/urllib3/connection.py", line 187, in connect
    conn = self._new_conn()
  File "/usr/local/lib/python3.6/dist-packages/urllib3/connection.py", line 172, in _new_conn
    self, "Failed to establish a new connection: %s" % e
urllib3.exceptions.NewConnectionError: <urllib3.connection.HTTPConnection object at 0x7f4f00072a58>: Failed to establish a new connection: [Errno 111] Connection refused

During handling of the above exception, another exception occurred:

Traceback (most recent call last):
  File "/usr/local/lib/python3.6/dist-packages/requests/adapters.py", line 449, in send
    timeout=timeout
  File "/usr/local/lib/python3.6/dist-packages/urllib3/connectionpool.py", line 725, in urlopen
    method, url, error=e, _pool=self, _stacktrace=sys.exc_info()[2]
  File "/usr/local/lib/python3.6/dist-packages/urllib3/util/retry.py", line 439, in increment
    raise MaxRetryError(_pool, url, error or ResponseError(cause))
urllib3.exceptions.MaxRetryError: HTTPConnectionPool(host='oj-backend', port=8000): Max retries exceeded with url: /api/judge_server_heartbeat/ (Caused by NewConnectionError('<urllib3.connection.HTTPConnection object at 0x7f4f00072a58>: Failed to establish a new connection: [Errno 111] Connection refused',))

During handling of the above exception, another exception occurred:

Traceback (most recent call last):
  File "/code/service.py", line 19, in _request
    "Content-Type": "application/json"}, timeout=5).text
  File "/usr/local/lib/python3.6/dist-packages/requests/api.py", line 119, in post
    return request('post', url, data=data, json=json, **kwargs)
  File "/usr/local/lib/python3.6/dist-packages/requests/api.py", line 61, in request
    return session.request(method=method, url=url, **kwargs)
  File "/usr/local/lib/python3.6/dist-packages/requests/sessions.py", line 530, in request
    resp = self.send(prep, **send_kwargs)
  File "/usr/local/lib/python3.6/dist-packages/requests/sessions.py", line 643, in send
    r = adapter.send(request, **kwargs)
  File "/usr/local/lib/python3.6/dist-packages/requests/adapters.py", line 516, in send
    raise ConnectionError(e, request=request)
requests.exceptions.ConnectionError: HTTPConnectionPool(host='oj-backend', port=8000): Max retries exceeded with url: /api/judge_server_heartbeat/ (Caused by NewConnectionError('<urllib3.connection.HTTPConnection object at 0x7f4f00072a58>: Failed to establish a new connection: [Errno 111] Connection refused',))

During handling of the above exception, another exception occurred:

Traceback (most recent call last):
  File "/code/service.py", line 42, in <module>
    service.heartbeat()
  File "/code/service.py", line 35, in heartbeat
    self._request(data)
  File "/code/service.py", line 22, in _request
    raise JudgeServiceError("Heartbeat request failed")
exception.JudgeServiceError
2021-06-28 03:16:30,840 ERROR HTTPConnectionPool(host='oj-backend', port=8000): Max retries exceeded with url: /api/judge_server_heartbeat/ (Caused by NewConnectionError('<urllib3.connection.HTTPConnection object at 0x7f4d2c3cea58>: Failed to establish a new connection: [Errno 111] Connection refused',))
Traceback (most recent call last):
  File "/usr/local/lib/python3.6/dist-packages/urllib3/connection.py", line 160, in _new_conn
    (self._dns_host, self.port), self.timeout, **extra_kw
  File "/usr/local/lib/python3.6/dist-packages/urllib3/util/connection.py", line 84, in create_connection
    raise err
  File "/usr/local/lib/python3.6/dist-packages/urllib3/util/connection.py", line 74, in create_connection
    sock.connect(sa)
ConnectionRefusedError: [Errno 111] Connection refused

During handling of the above exception, another exception occurred:

Traceback (most recent call last):
  File "/usr/local/lib/python3.6/dist-packages/urllib3/connectionpool.py", line 677, in urlopen
    chunked=chunked,
  File "/usr/local/lib/python3.6/dist-packages/urllib3/connectionpool.py", line 392, in _make_request
    conn.request(method, url, **httplib_request_kw)
  File "/usr/lib/python3.6/http/client.py", line 1264, in request
    self._send_request(method, url, body, headers, encode_chunked)
  File "/usr/lib/python3.6/http/client.py", line 1310, in _send_request
    self.endheaders(body, encode_chunked=encode_chunked)
  File "/usr/lib/python3.6/http/client.py", line 1259, in endheaders
    self._send_output(message_body, encode_chunked=encode_chunked)
  File "/usr/lib/python3.6/http/client.py", line 1038, in _send_output
    self.send(msg)
  File "/usr/lib/python3.6/http/client.py", line 976, in send
    self.connect()
  File "/usr/local/lib/python3.6/dist-packages/urllib3/connection.py", line 187, in connect
    conn = self._new_conn()
  File "/usr/local/lib/python3.6/dist-packages/urllib3/connection.py", line 172, in _new_conn
    self, "Failed to establish a new connection: %s" % e
urllib3.exceptions.NewConnectionError: <urllib3.connection.HTTPConnection object at 0x7f4d2c3cea58>: Failed to establish a new connection: [Errno 111] Connection refused

During handling of the above exception, another exception occurred:

Traceback (most recent call last):
  File "/usr/local/lib/python3.6/dist-packages/requests/adapters.py", line 449, in send
    timeout=timeout
  File "/usr/local/lib/python3.6/dist-packages/urllib3/connectionpool.py", line 725, in urlopen
    method, url, error=e, _pool=self, _stacktrace=sys.exc_info()[2]
  File "/usr/local/lib/python3.6/dist-packages/urllib3/util/retry.py", line 439, in increment
    raise MaxRetryError(_pool, url, error or ResponseError(cause))
urllib3.exceptions.MaxRetryError: HTTPConnectionPool(host='oj-backend', port=8000): Max retries exceeded with url: /api/judge_server_heartbeat/ (Caused by NewConnectionError('<urllib3.connection.HTTPConnection object at 0x7f4d2c3cea58>: Failed to establish a new connection: [Errno 111] Connection refused',))

During handling of the above exception, another exception occurred:

Traceback (most recent call last):
  File "/code/service.py", line 19, in _request
    "Content-Type": "application/json"}, timeout=5).text
  File "/usr/local/lib/python3.6/dist-packages/requests/api.py", line 119, in post
    return request('post', url, data=data, json=json, **kwargs)
  File "/usr/local/lib/python3.6/dist-packages/requests/api.py", line 61, in request
    return session.request(method=method, url=url, **kwargs)
  File "/usr/local/lib/python3.6/dist-packages/requests/sessions.py", line 530, in request
    resp = self.send(prep, **send_kwargs)
  File "/usr/local/lib/python3.6/dist-packages/requests/sessions.py", line 643, in send
    r = adapter.send(request, **kwargs)
  File "/usr/local/lib/python3.6/dist-packages/requests/adapters.py", line 516, in send
    raise ConnectionError(e, request=request)
requests.exceptions.ConnectionError: HTTPConnectionPool(host='oj-backend', port=8000): Max retries exceeded with url: /api/judge_server_heartbeat/ (Caused by NewConnectionError('<urllib3.connection.HTTPConnection object at 0x7f4d2c3cea58>: Failed to establish a new connection: [Errno 111] Connection refused',))
2021-06-28 03:16:30,845 ERROR 
Traceback (most recent call last):
  File "/usr/local/lib/python3.6/dist-packages/urllib3/connection.py", line 160, in _new_conn
    (self._dns_host, self.port), self.timeout, **extra_kw
  File "/usr/local/lib/python3.6/dist-packages/urllib3/util/connection.py", line 84, in create_connection
    raise err
  File "/usr/local/lib/python3.6/dist-packages/urllib3/util/connection.py", line 74, in create_connection
    sock.connect(sa)
ConnectionRefusedError: [Errno 111] Connection refused

During handling of the above exception, another exception occurred:

Traceback (most recent call last):
  File "/usr/local/lib/python3.6/dist-packages/urllib3/connectionpool.py", line 677, in urlopen
    chunked=chunked,
  File "/usr/local/lib/python3.6/dist-packages/urllib3/connectionpool.py", line 392, in _make_request
    conn.request(method, url, **httplib_request_kw)
  File "/usr/lib/python3.6/http/client.py", line 1264, in request
    self._send_request(method, url, body, headers, encode_chunked)
  File "/usr/lib/python3.6/http/client.py", line 1310, in _send_request
    self.endheaders(body, encode_chunked=encode_chunked)
  File "/usr/lib/python3.6/http/client.py", line 1259, in endheaders
    self._send_output(message_body, encode_chunked=encode_chunked)
  File "/usr/lib/python3.6/http/client.py", line 1038, in _send_output
    self.send(msg)
  File "/usr/lib/python3.6/http/client.py", line 976, in send
    self.connect()
  File "/usr/local/lib/python3.6/dist-packages/urllib3/connection.py", line 187, in connect
    conn = self._new_conn()
  File "/usr/local/lib/python3.6/dist-packages/urllib3/connection.py", line 172, in _new_conn
    self, "Failed to establish a new connection: %s" % e
urllib3.exceptions.NewConnectionError: <urllib3.connection.HTTPConnection object at 0x7f4d2c3cea58>: Failed to establish a new connection: [Errno 111] Connection refused

During handling of the above exception, another exception occurred:

Traceback (most recent call last):
  File "/usr/local/lib/python3.6/dist-packages/requests/adapters.py", line 449, in send
    timeout=timeout
  File "/usr/local/lib/python3.6/dist-packages/urllib3/connectionpool.py", line 725, in urlopen
    method, url, error=e, _pool=self, _stacktrace=sys.exc_info()[2]
  File "/usr/local/lib/python3.6/dist-packages/urllib3/util/retry.py", line 439, in increment
    raise MaxRetryError(_pool, url, error or ResponseError(cause))
urllib3.exceptions.MaxRetryError: HTTPConnectionPool(host='oj-backend', port=8000): Max retries exceeded with url: /api/judge_server_heartbeat/ (Caused by NewConnectionError('<urllib3.connection.HTTPConnection object at 0x7f4d2c3cea58>: Failed to establish a new connection: [Errno 111] Connection refused',))

During handling of the above exception, another exception occurred:

Traceback (most recent call last):
  File "/code/service.py", line 19, in _request
    "Content-Type": "application/json"}, timeout=5).text
  File "/usr/local/lib/python3.6/dist-packages/requests/api.py", line 119, in post
    return request('post', url, data=data, json=json, **kwargs)
  File "/usr/local/lib/python3.6/dist-packages/requests/api.py", line 61, in request
    return session.request(method=method, url=url, **kwargs)
  File "/usr/local/lib/python3.6/dist-packages/requests/sessions.py", line 530, in request
    resp = self.send(prep, **send_kwargs)
  File "/usr/local/lib/python3.6/dist-packages/requests/sessions.py", line 643, in send
    r = adapter.send(request, **kwargs)
  File "/usr/local/lib/python3.6/dist-packages/requests/adapters.py", line 516, in send
    raise ConnectionError(e, request=request)
requests.exceptions.ConnectionError: HTTPConnectionPool(host='oj-backend', port=8000): Max retries exceeded with url: /api/judge_server_heartbeat/ (Caused by NewConnectionError('<urllib3.connection.HTTPConnection object at 0x7f4d2c3cea58>: Failed to establish a new connection: [Errno 111] Connection refused',))

During handling of the above exception, another exception occurred:

Traceback (most recent call last):
  File "/code/service.py", line 42, in <module>
    service.heartbeat()
  File "/code/service.py", line 35, in heartbeat
    self._request(data)
  File "/code/service.py", line 22, in _request
    raise JudgeServiceError("Heartbeat request failed")
exception.JudgeServiceError
2021-06-28 03:16:36,175 ERROR HTTPConnectionPool(host='oj-backend', port=8000): Max retries exceeded with url: /api/judge_server_heartbeat/ (Caused by NewConnectionError('<urllib3.connection.HTTPConnection object at 0x7fce4a4f7a58>: Failed to establish a new connection: [Errno 111] Connection refused',))
Traceback (most recent call last):
  File "/usr/local/lib/python3.6/dist-packages/urllib3/connection.py", line 160, in _new_conn
    (self._dns_host, self.port), self.timeout, **extra_kw
  File "/usr/local/lib/python3.6/dist-packages/urllib3/util/connection.py", line 84, in create_connection
    raise err
  File "/usr/local/lib/python3.6/dist-packages/urllib3/util/connection.py", line 74, in create_connection
    sock.connect(sa)
ConnectionRefusedError: [Errno 111] Connection refused

During handling of the above exception, another exception occurred:

Traceback (most recent call last):
  File "/usr/local/lib/python3.6/dist-packages/urllib3/connectionpool.py", line 677, in urlopen
    chunked=chunked,
  File "/usr/local/lib/python3.6/dist-packages/urllib3/connectionpool.py", line 392, in _make_request
    conn.request(method, url, **httplib_request_kw)
  File "/usr/lib/python3.6/http/client.py", line 1264, in request
    self._send_request(method, url, body, headers, encode_chunked)
  File "/usr/lib/python3.6/http/client.py", line 1310, in _send_request
    self.endheaders(body, encode_chunked=encode_chunked)
  File "/usr/lib/python3.6/http/client.py", line 1259, in endheaders
    self._send_output(message_body, encode_chunked=encode_chunked)
  File "/usr/lib/python3.6/http/client.py", line 1038, in _send_output
    self.send(msg)
  File "/usr/lib/python3.6/http/client.py", line 976, in send
    self.connect()
  File "/usr/local/lib/python3.6/dist-packages/urllib3/connection.py", line 187, in connect
    conn = self._new_conn()
  File "/usr/local/lib/python3.6/dist-packages/urllib3/connection.py", line 172, in _new_conn
    self, "Failed to establish a new connection: %s" % e
urllib3.exceptions.NewConnectionError: <urllib3.connection.HTTPConnection object at 0x7fce4a4f7a58>: Failed to establish a new connection: [Errno 111] Connection refused

During handling of the above exception, another exception occurred:

Traceback (most recent call last):
  File "/usr/local/lib/python3.6/dist-packages/requests/adapters.py", line 449, in send
    timeout=timeout
  File "/usr/local/lib/python3.6/dist-packages/urllib3/connectionpool.py", line 725, in urlopen
    method, url, error=e, _pool=self, _stacktrace=sys.exc_info()[2]
  File "/usr/local/lib/python3.6/dist-packages/urllib3/util/retry.py", line 439, in increment
    raise MaxRetryError(_pool, url, error or ResponseError(cause))
urllib3.exceptions.MaxRetryError: HTTPConnectionPool(host='oj-backend', port=8000): Max retries exceeded with url: /api/judge_server_heartbeat/ (Caused by NewConnectionError('<urllib3.connection.HTTPConnection object at 0x7fce4a4f7a58>: Failed to establish a new connection: [Errno 111] Connection refused',))

During handling of the above exception, another exception occurred:

Traceback (most recent call last):
  File "/code/service.py", line 19, in _request
    "Content-Type": "application/json"}, timeout=5).text
  File "/usr/local/lib/python3.6/dist-packages/requests/api.py", line 119, in post
    return request('post', url, data=data, json=json, **kwargs)
  File "/usr/local/lib/python3.6/dist-packages/requests/api.py", line 61, in request
    return session.request(method=method, url=url, **kwargs)
  File "/usr/local/lib/python3.6/dist-packages/requests/sessions.py", line 530, in request
    resp = self.send(prep, **send_kwargs)
  File "/usr/local/lib/python3.6/dist-packages/requests/sessions.py", line 643, in send
    r = adapter.send(request, **kwargs)
  File "/usr/local/lib/python3.6/dist-packages/requests/adapters.py", line 516, in send
    raise ConnectionError(e, request=request)
requests.exceptions.ConnectionError: HTTPConnectionPool(host='oj-backend', port=8000): Max retries exceeded with url: /api/judge_server_heartbeat/ (Caused by NewConnectionError('<urllib3.connection.HTTPConnection object at 0x7fce4a4f7a58>: Failed to establish a new connection: [Errno 111] Connection refused',))
2021-06-28 03:16:36,180 ERROR 
Traceback (most recent call last):
  File "/usr/local/lib/python3.6/dist-packages/urllib3/connection.py", line 160, in _new_conn
    (self._dns_host, self.port), self.timeout, **extra_kw
  File "/usr/local/lib/python3.6/dist-packages/urllib3/util/connection.py", line 84, in create_connection
    raise err
  File "/usr/local/lib/python3.6/dist-packages/urllib3/util/connection.py", line 74, in create_connection
    sock.connect(sa)
ConnectionRefusedError: [Errno 111] Connection refused

During handling of the above exception, another exception occurred:

Traceback (most recent call last):
  File "/usr/local/lib/python3.6/dist-packages/urllib3/connectionpool.py", line 677, in urlopen
    chunked=chunked,
  File "/usr/local/lib/python3.6/dist-packages/urllib3/connectionpool.py", line 392, in _make_request
    conn.request(method, url, **httplib_request_kw)
  File "/usr/lib/python3.6/http/client.py", line 1264, in request
    self._send_request(method, url, body, headers, encode_chunked)
  File "/usr/lib/python3.6/http/client.py", line 1310, in _send_request
    self.endheaders(body, encode_chunked=encode_chunked)
  File "/usr/lib/python3.6/http/client.py", line 1259, in endheaders
    self._send_output(message_body, encode_chunked=encode_chunked)
  File "/usr/lib/python3.6/http/client.py", line 1038, in _send_output
    self.send(msg)
  File "/usr/lib/python3.6/http/client.py", line 976, in send
    self.connect()
  File "/usr/local/lib/python3.6/dist-packages/urllib3/connection.py", line 187, in connect
    conn = self._new_conn()
  File "/usr/local/lib/python3.6/dist-packages/urllib3/connection.py", line 172, in _new_conn
    self, "Failed to establish a new connection: %s" % e
urllib3.exceptions.NewConnectionError: <urllib3.connection.HTTPConnection object at 0x7fce4a4f7a58>: Failed to establish a new connection: [Errno 111] Connection refused

During handling of the above exception, another exception occurred:

Traceback (most recent call last):
  File "/usr/local/lib/python3.6/dist-packages/requests/adapters.py", line 449, in send
    timeout=timeout
  File "/usr/local/lib/python3.6/dist-packages/urllib3/connectionpool.py", line 725, in urlopen
    method, url, error=e, _pool=self, _stacktrace=sys.exc_info()[2]
  File "/usr/local/lib/python3.6/dist-packages/urllib3/util/retry.py", line 439, in increment
    raise MaxRetryError(_pool, url, error or ResponseError(cause))
urllib3.exceptions.MaxRetryError: HTTPConnectionPool(host='oj-backend', port=8000): Max retries exceeded with url: /api/judge_server_heartbeat/ (Caused by NewConnectionError('<urllib3.connection.HTTPConnection object at 0x7fce4a4f7a58>: Failed to establish a new connection: [Errno 111] Connection refused',))

During handling of the above exception, another exception occurred:

Traceback (most recent call last):
  File "/code/service.py", line 19, in _request
    "Content-Type": "application/json"}, timeout=5).text
  File "/usr/local/lib/python3.6/dist-packages/requests/api.py", line 119, in post
    return request('post', url, data=data, json=json, **kwargs)
  File "/usr/local/lib/python3.6/dist-packages/requests/api.py", line 61, in request
    return session.request(method=method, url=url, **kwargs)
  File "/usr/local/lib/python3.6/dist-packages/requests/sessions.py", line 530, in request
    resp = self.send(prep, **send_kwargs)
  File "/usr/local/lib/python3.6/dist-packages/requests/sessions.py", line 643, in send
    r = adapter.send(request, **kwargs)
  File "/usr/local/lib/python3.6/dist-packages/requests/adapters.py", line 516, in send
    raise ConnectionError(e, request=request)
requests.exceptions.ConnectionError: HTTPConnectionPool(host='oj-backend', port=8000): Max retries exceeded with url: /api/judge_server_heartbeat/ (Caused by NewConnectionError('<urllib3.connection.HTTPConnection object at 0x7fce4a4f7a58>: Failed to establish a new connection: [Errno 111] Connection refused',))

During handling of the above exception, another exception occurred:

Traceback (most recent call last):
  File "/code/service.py", line 42, in <module>
    service.heartbeat()
  File "/code/service.py", line 35, in heartbeat
    self._request(data)
  File "/code/service.py", line 22, in _request
    raise JudgeServiceError("Heartbeat request failed")
exception.JudgeServiceError
2021-06-28 03:16:42,003 ERROR HTTPConnectionPool(host='oj-backend', port=8000): Max retries exceeded with url: /api/judge_server_heartbeat/ (Caused by NewConnectionError('<urllib3.connection.HTTPConnection object at 0x7fb29dc5da90>: Failed to establish a new connection: [Errno 111] Connection refused',))
Traceback (most recent call last):
  File "/usr/local/lib/python3.6/dist-packages/urllib3/connection.py", line 160, in _new_conn
    (self._dns_host, self.port), self.timeout, **extra_kw
  File "/usr/local/lib/python3.6/dist-packages/urllib3/util/connection.py", line 84, in create_connection
    raise err
  File "/usr/local/lib/python3.6/dist-packages/urllib3/util/connection.py", line 74, in create_connection
    sock.connect(sa)
ConnectionRefusedError: [Errno 111] Connection refused

During handling of the above exception, another exception occurred:

Traceback (most recent call last):
  File "/usr/local/lib/python3.6/dist-packages/urllib3/connectionpool.py", line 677, in urlopen
    chunked=chunked,
  File "/usr/local/lib/python3.6/dist-packages/urllib3/connectionpool.py", line 392, in _make_request
    conn.request(method, url, **httplib_request_kw)
  File "/usr/lib/python3.6/http/client.py", line 1264, in request
    self._send_request(method, url, body, headers, encode_chunked)
  File "/usr/lib/python3.6/http/client.py", line 1310, in _send_request
    self.endheaders(body, encode_chunked=encode_chunked)
  File "/usr/lib/python3.6/http/client.py", line 1259, in endheaders
    self._send_output(message_body, encode_chunked=encode_chunked)
  File "/usr/lib/python3.6/http/client.py", line 1038, in _send_output
    self.send(msg)
  File "/usr/lib/python3.6/http/client.py", line 976, in send
    self.connect()
  File "/usr/local/lib/python3.6/dist-packages/urllib3/connection.py", line 187, in connect
    conn = self._new_conn()
  File "/usr/local/lib/python3.6/dist-packages/urllib3/connection.py", line 172, in _new_conn
    self, "Failed to establish a new connection: %s" % e
urllib3.exceptions.NewConnectionError: <urllib3.connection.HTTPConnection object at 0x7fb29dc5da90>: Failed to establish a new connection: [Errno 111] Connection refused

During handling of the above exception, another exception occurred:

Traceback (most recent call last):
  File "/usr/local/lib/python3.6/dist-packages/requests/adapters.py", line 449, in send
    timeout=timeout
  File "/usr/local/lib/python3.6/dist-packages/urllib3/connectionpool.py", line 725, in urlopen
    method, url, error=e, _pool=self, _stacktrace=sys.exc_info()[2]
  File "/usr/local/lib/python3.6/dist-packages/urllib3/util/retry.py", line 439, in increment
    raise MaxRetryError(_pool, url, error or ResponseError(cause))
urllib3.exceptions.MaxRetryError: HTTPConnectionPool(host='oj-backend', port=8000): Max retries exceeded with url: /api/judge_server_heartbeat/ (Caused by NewConnectionError('<urllib3.connection.HTTPConnection object at 0x7fb29dc5da90>: Failed to establish a new connection: [Errno 111] Connection refused',))

During handling of the above exception, another exception occurred:

Traceback (most recent call last):
  File "/code/service.py", line 19, in _request
    "Content-Type": "application/json"}, timeout=5).text
  File "/usr/local/lib/python3.6/dist-packages/requests/api.py", line 119, in post
    return request('post', url, data=data, json=json, **kwargs)
  File "/usr/local/lib/python3.6/dist-packages/requests/api.py", line 61, in request
    return session.request(method=method, url=url, **kwargs)
  File "/usr/local/lib/python3.6/dist-packages/requests/sessions.py", line 530, in request
    resp = self.send(prep, **send_kwargs)
  File "/usr/local/lib/python3.6/dist-packages/requests/sessions.py", line 643, in send
    r = adapter.send(request, **kwargs)
  File "/usr/local/lib/python3.6/dist-packages/requests/adapters.py", line 516, in send
    raise ConnectionError(e, request=request)
requests.exceptions.ConnectionError: HTTPConnectionPool(host='oj-backend', port=8000): Max retries exceeded with url: /api/judge_server_heartbeat/ (Caused by NewConnectionError('<urllib3.connection.HTTPConnection object at 0x7fb29dc5da90>: Failed to establish a new connection: [Errno 111] Connection refused',))
2021-06-28 03:16:42,009 ERROR 
Traceback (most recent call last):
  File "/usr/local/lib/python3.6/dist-packages/urllib3/connection.py", line 160, in _new_conn
    (self._dns_host, self.port), self.timeout, **extra_kw
  File "/usr/local/lib/python3.6/dist-packages/urllib3/util/connection.py", line 84, in create_connection
    raise err
  File "/usr/local/lib/python3.6/dist-packages/urllib3/util/connection.py", line 74, in create_connection
    sock.connect(sa)
ConnectionRefusedError: [Errno 111] Connection refused

During handling of the above exception, another exception occurred:

Traceback (most recent call last):
  File "/usr/local/lib/python3.6/dist-packages/urllib3/connectionpool.py", line 677, in urlopen
    chunked=chunked,
  File "/usr/local/lib/python3.6/dist-packages/urllib3/connectionpool.py", line 392, in _make_request
    conn.request(method, url, **httplib_request_kw)
  File "/usr/lib/python3.6/http/client.py", line 1264, in request
    self._send_request(method, url, body, headers, encode_chunked)
  File "/usr/lib/python3.6/http/client.py", line 1310, in _send_request
    self.endheaders(body, encode_chunked=encode_chunked)
  File "/usr/lib/python3.6/http/client.py", line 1259, in endheaders
    self._send_output(message_body, encode_chunked=encode_chunked)
  File "/usr/lib/python3.6/http/client.py", line 1038, in _send_output
    self.send(msg)
  File "/usr/lib/python3.6/http/client.py", line 976, in send
    self.connect()
  File "/usr/local/lib/python3.6/dist-packages/urllib3/connection.py", line 187, in connect
    conn = self._new_conn()
  File "/usr/local/lib/python3.6/dist-packages/urllib3/connection.py", line 172, in _new_conn
    self, "Failed to establish a new connection: %s" % e
urllib3.exceptions.NewConnectionError: <urllib3.connection.HTTPConnection object at 0x7fb29dc5da90>: Failed to establish a new connection: [Errno 111] Connection refused

During handling of the above exception, another exception occurred:

Traceback (most recent call last):
  File "/usr/local/lib/python3.6/dist-packages/requests/adapters.py", line 449, in send
    timeout=timeout
  File "/usr/local/lib/python3.6/dist-packages/urllib3/connectionpool.py", line 725, in urlopen
    method, url, error=e, _pool=self, _stacktrace=sys.exc_info()[2]
  File "/usr/local/lib/python3.6/dist-packages/urllib3/util/retry.py", line 439, in increment
    raise MaxRetryError(_pool, url, error or ResponseError(cause))
urllib3.exceptions.MaxRetryError: HTTPConnectionPool(host='oj-backend', port=8000): Max retries exceeded with url: /api/judge_server_heartbeat/ (Caused by NewConnectionError('<urllib3.connection.HTTPConnection object at 0x7fb29dc5da90>: Failed to establish a new connection: [Errno 111] Connection refused',))

During handling of the above exception, another exception occurred:

Traceback (most recent call last):
  File "/code/service.py", line 19, in _request
    "Content-Type": "application/json"}, timeout=5).text
  File "/usr/local/lib/python3.6/dist-packages/requests/api.py", line 119, in post
    return request('post', url, data=data, json=json, **kwargs)
  File "/usr/local/lib/python3.6/dist-packages/requests/api.py", line 61, in request
    return session.request(method=method, url=url, **kwargs)
  File "/usr/local/lib/python3.6/dist-packages/requests/sessions.py", line 530, in request
    resp = self.send(prep, **send_kwargs)
  File "/usr/local/lib/python3.6/dist-packages/requests/sessions.py", line 643, in send
    r = adapter.send(request, **kwargs)
  File "/usr/local/lib/python3.6/dist-packages/requests/adapters.py", line 516, in send
    raise ConnectionError(e, request=request)
requests.exceptions.ConnectionError: HTTPConnectionPool(host='oj-backend', port=8000): Max retries exceeded with url: /api/judge_server_heartbeat/ (Caused by NewConnectionError('<urllib3.connection.HTTPConnection object at 0x7fb29dc5da90>: Failed to establish a new connection: [Errno 111] Connection refused',))

During handling of the above exception, another exception occurred:

Traceback (most recent call last):
  File "/code/service.py", line 42, in <module>
    service.heartbeat()
  File "/code/service.py", line 35, in heartbeat
    self._request(data)
  File "/code/service.py", line 22, in _request
    raise JudgeServiceError("Heartbeat request failed")
exception.JudgeServiceError
2021-06-28 03:16:47,524 ERROR HTTPConnectionPool(host='oj-backend', port=8000): Max retries exceeded with url: /api/judge_server_heartbeat/ (Caused by NewConnectionError('<urllib3.connection.HTTPConnection object at 0x7f4985f98a58>: Failed to establish a new connection: [Errno 111] Connection refused',))
Traceback (most recent call last):
  File "/usr/local/lib/python3.6/dist-packages/urllib3/connection.py", line 160, in _new_conn
    (self._dns_host, self.port), self.timeout, **extra_kw
  File "/usr/local/lib/python3.6/dist-packages/urllib3/util/connection.py", line 84, in create_connection
    raise err
  File "/usr/local/lib/python3.6/dist-packages/urllib3/util/connection.py", line 74, in create_connection
    sock.connect(sa)
ConnectionRefusedError: [Errno 111] Connection refused

During handling of the above exception, another exception occurred:

Traceback (most recent call last):
  File "/usr/local/lib/python3.6/dist-packages/urllib3/connectionpool.py", line 677, in urlopen
    chunked=chunked,
  File "/usr/local/lib/python3.6/dist-packages/urllib3/connectionpool.py", line 392, in _make_request
    conn.request(method, url, **httplib_request_kw)
  File "/usr/lib/python3.6/http/client.py", line 1264, in request
    self._send_request(method, url, body, headers, encode_chunked)
  File "/usr/lib/python3.6/http/client.py", line 1310, in _send_request
    self.endheaders(body, encode_chunked=encode_chunked)
  File "/usr/lib/python3.6/http/client.py", line 1259, in endheaders
    self._send_output(message_body, encode_chunked=encode_chunked)
  File "/usr/lib/python3.6/http/client.py", line 1038, in _send_output
    self.send(msg)
  File "/usr/lib/python3.6/http/client.py", line 976, in send
    self.connect()
  File "/usr/local/lib/python3.6/dist-packages/urllib3/connection.py", line 187, in connect
    conn = self._new_conn()
  File "/usr/local/lib/python3.6/dist-packages/urllib3/connection.py", line 172, in _new_conn
    self, "Failed to establish a new connection: %s" % e
urllib3.exceptions.NewConnectionError: <urllib3.connection.HTTPConnection object at 0x7f4985f98a58>: Failed to establish a new connection: [Errno 111] Connection refused

During handling of the above exception, another exception occurred:

Traceback (most recent call last):
  File "/usr/local/lib/python3.6/dist-packages/requests/adapters.py", line 449, in send
    timeout=timeout
  File "/usr/local/lib/python3.6/dist-packages/urllib3/connectionpool.py", line 725, in urlopen
    method, url, error=e, _pool=self, _stacktrace=sys.exc_info()[2]
  File "/usr/local/lib/python3.6/dist-packages/urllib3/util/retry.py", line 439, in increment
    raise MaxRetryError(_pool, url, error or ResponseError(cause))
urllib3.exceptions.MaxRetryError: HTTPConnectionPool(host='oj-backend', port=8000): Max retries exceeded with url: /api/judge_server_heartbeat/ (Caused by NewConnectionError('<urllib3.connection.HTTPConnection object at 0x7f4985f98a58>: Failed to establish a new connection: [Errno 111] Connection refused',))

During handling of the above exception, another exception occurred:

Traceback (most recent call last):
  File "/code/service.py", line 19, in _request
    "Content-Type": "application/json"}, timeout=5).text
  File "/usr/local/lib/python3.6/dist-packages/requests/api.py", line 119, in post
    return request('post', url, data=data, json=json, **kwargs)
  File "/usr/local/lib/python3.6/dist-packages/requests/api.py", line 61, in request
    return session.request(method=method, url=url, **kwargs)
  File "/usr/local/lib/python3.6/dist-packages/requests/sessions.py", line 530, in request
    resp = self.send(prep, **send_kwargs)
  File "/usr/local/lib/python3.6/dist-packages/requests/sessions.py", line 643, in send
    r = adapter.send(request, **kwargs)
  File "/usr/local/lib/python3.6/dist-packages/requests/adapters.py", line 516, in send
    raise ConnectionError(e, request=request)
requests.exceptions.ConnectionError: HTTPConnectionPool(host='oj-backend', port=8000): Max retries exceeded with url: /api/judge_server_heartbeat/ (Caused by NewConnectionError('<urllib3.connection.HTTPConnection object at 0x7f4985f98a58>: Failed to establish a new connection: [Errno 111] Connection refused',))
2021-06-28 03:16:47,531 ERROR 
Traceback (most recent call last):
  File "/usr/local/lib/python3.6/dist-packages/urllib3/connection.py", line 160, in _new_conn
    (self._dns_host, self.port), self.timeout, **extra_kw
  File "/usr/local/lib/python3.6/dist-packages/urllib3/util/connection.py", line 84, in create_connection
    raise err
  File "/usr/local/lib/python3.6/dist-packages/urllib3/util/connection.py", line 74, in create_connection
    sock.connect(sa)
ConnectionRefusedError: [Errno 111] Connection refused

During handling of the above exception, another exception occurred:

Traceback (most recent call last):
  File "/usr/local/lib/python3.6/dist-packages/urllib3/connectionpool.py", line 677, in urlopen
    chunked=chunked,
  File "/usr/local/lib/python3.6/dist-packages/urllib3/connectionpool.py", line 392, in _make_request
    conn.request(method, url, **httplib_request_kw)
  File "/usr/lib/python3.6/http/client.py", line 1264, in request
    self._send_request(method, url, body, headers, encode_chunked)
  File "/usr/lib/python3.6/http/client.py", line 1310, in _send_request
    self.endheaders(body, encode_chunked=encode_chunked)
  File "/usr/lib/python3.6/http/client.py", line 1259, in endheaders
    self._send_output(message_body, encode_chunked=encode_chunked)
  File "/usr/lib/python3.6/http/client.py", line 1038, in _send_output
    self.send(msg)
  File "/usr/lib/python3.6/http/client.py", line 976, in send
    self.connect()
  File "/usr/local/lib/python3.6/dist-packages/urllib3/connection.py", line 187, in connect
    conn = self._new_conn()
  File "/usr/local/lib/python3.6/dist-packages/urllib3/connection.py", line 172, in _new_conn
    self, "Failed to establish a new connection: %s" % e
urllib3.exceptions.NewConnectionError: <urllib3.connection.HTTPConnection object at 0x7f4985f98a58>: Failed to establish a new connection: [Errno 111] Connection refused

During handling of the above exception, another exception occurred:

Traceback (most recent call last):
  File "/usr/local/lib/python3.6/dist-packages/requests/adapters.py", line 449, in send
    timeout=timeout
  File "/usr/local/lib/python3.6/dist-packages/urllib3/connectionpool.py", line 725, in urlopen
    method, url, error=e, _pool=self, _stacktrace=sys.exc_info()[2]
  File "/usr/local/lib/python3.6/dist-packages/urllib3/util/retry.py", line 439, in increment
    raise MaxRetryError(_pool, url, error or ResponseError(cause))
urllib3.exceptions.MaxRetryError: HTTPConnectionPool(host='oj-backend', port=8000): Max retries exceeded with url: /api/judge_server_heartbeat/ (Caused by NewConnectionError('<urllib3.connection.HTTPConnection object at 0x7f4985f98a58>: Failed to establish a new connection: [Errno 111] Connection refused',))

During handling of the above exception, another exception occurred:

Traceback (most recent call last):
  File "/code/service.py", line 19, in _request
    "Content-Type": "application/json"}, timeout=5).text
  File "/usr/local/lib/python3.6/dist-packages/requests/api.py", line 119, in post
    return request('post', url, data=data, json=json, **kwargs)
  File "/usr/local/lib/python3.6/dist-packages/requests/api.py", line 61, in request
    return session.request(method=method, url=url, **kwargs)
  File "/usr/local/lib/python3.6/dist-packages/requests/sessions.py", line 530, in request
    resp = self.send(prep, **send_kwargs)
  File "/usr/local/lib/python3.6/dist-packages/requests/sessions.py", line 643, in send
    r = adapter.send(request, **kwargs)
  File "/usr/local/lib/python3.6/dist-packages/requests/adapters.py", line 516, in send
    raise ConnectionError(e, request=request)
requests.exceptions.ConnectionError: HTTPConnectionPool(host='oj-backend', port=8000): Max retries exceeded with url: /api/judge_server_heartbeat/ (Caused by NewConnectionError('<urllib3.connection.HTTPConnection object at 0x7f4985f98a58>: Failed to establish a new connection: [Errno 111] Connection refused',))

During handling of the above exception, another exception occurred:

Traceback (most recent call last):
  File "/code/service.py", line 42, in <module>
    service.heartbeat()
  File "/code/service.py", line 35, in heartbeat
    self._request(data)
  File "/code/service.py", line 22, in _request
    raise JudgeServiceError("Heartbeat request failed")
exception.JudgeServiceError
2021-06-28 04:01:20,773 ERROR HTTPConnectionPool(host='oj-backend', port=8000): Max retries exceeded with url: /api/judge_server_heartbeat/ (Caused by NewConnectionError('<urllib3.connection.HTTPConnection object at 0x7f860bf90a58>: Failed to establish a new connection: [Errno 111] Connection refused',))
Traceback (most recent call last):
  File "/usr/local/lib/python3.6/dist-packages/urllib3/connection.py", line 160, in _new_conn
    (self._dns_host, self.port), self.timeout, **extra_kw
  File "/usr/local/lib/python3.6/dist-packages/urllib3/util/connection.py", line 84, in create_connection
    raise err
  File "/usr/local/lib/python3.6/dist-packages/urllib3/util/connection.py", line 74, in create_connection
    sock.connect(sa)
ConnectionRefusedError: [Errno 111] Connection refused

During handling of the above exception, another exception occurred:

Traceback (most recent call last):
  File "/usr/local/lib/python3.6/dist-packages/urllib3/connectionpool.py", line 677, in urlopen
    chunked=chunked,
  File "/usr/local/lib/python3.6/dist-packages/urllib3/connectionpool.py", line 392, in _make_request
    conn.request(method, url, **httplib_request_kw)
  File "/usr/lib/python3.6/http/client.py", line 1264, in request
    self._send_request(method, url, body, headers, encode_chunked)
  File "/usr/lib/python3.6/http/client.py", line 1310, in _send_request
    self.endheaders(body, encode_chunked=encode_chunked)
  File "/usr/lib/python3.6/http/client.py", line 1259, in endheaders
    self._send_output(message_body, encode_chunked=encode_chunked)
  File "/usr/lib/python3.6/http/client.py", line 1038, in _send_output
    self.send(msg)
  File "/usr/lib/python3.6/http/client.py", line 976, in send
    self.connect()
  File "/usr/local/lib/python3.6/dist-packages/urllib3/connection.py", line 187, in connect
    conn = self._new_conn()
  File "/usr/local/lib/python3.6/dist-packages/urllib3/connection.py", line 172, in _new_conn
    self, "Failed to establish a new connection: %s" % e
urllib3.exceptions.NewConnectionError: <urllib3.connection.HTTPConnection object at 0x7f860bf90a58>: Failed to establish a new connection: [Errno 111] Connection refused

During handling of the above exception, another exception occurred:

Traceback (most recent call last):
  File "/usr/local/lib/python3.6/dist-packages/requests/adapters.py", line 449, in send
    timeout=timeout
  File "/usr/local/lib/python3.6/dist-packages/urllib3/connectionpool.py", line 725, in urlopen
    method, url, error=e, _pool=self, _stacktrace=sys.exc_info()[2]
  File "/usr/local/lib/python3.6/dist-packages/urllib3/util/retry.py", line 439, in increment
    raise MaxRetryError(_pool, url, error or ResponseError(cause))
urllib3.exceptions.MaxRetryError: HTTPConnectionPool(host='oj-backend', port=8000): Max retries exceeded with url: /api/judge_server_heartbeat/ (Caused by NewConnectionError('<urllib3.connection.HTTPConnection object at 0x7f860bf90a58>: Failed to establish a new connection: [Errno 111] Connection refused',))

During handling of the above exception, another exception occurred:

Traceback (most recent call last):
  File "/code/service.py", line 19, in _request
    "Content-Type": "application/json"}, timeout=5).text
  File "/usr/local/lib/python3.6/dist-packages/requests/api.py", line 119, in post
    return request('post', url, data=data, json=json, **kwargs)
  File "/usr/local/lib/python3.6/dist-packages/requests/api.py", line 61, in request
    return session.request(method=method, url=url, **kwargs)
  File "/usr/local/lib/python3.6/dist-packages/requests/sessions.py", line 530, in request
    resp = self.send(prep, **send_kwargs)
  File "/usr/local/lib/python3.6/dist-packages/requests/sessions.py", line 643, in send
    r = adapter.send(request, **kwargs)
  File "/usr/local/lib/python3.6/dist-packages/requests/adapters.py", line 516, in send
    raise ConnectionError(e, request=request)
requests.exceptions.ConnectionError: HTTPConnectionPool(host='oj-backend', port=8000): Max retries exceeded with url: /api/judge_server_heartbeat/ (Caused by NewConnectionError('<urllib3.connection.HTTPConnection object at 0x7f860bf90a58>: Failed to establish a new connection: [Errno 111] Connection refused',))
2021-06-28 04:01:20,832 ERROR 
Traceback (most recent call last):
  File "/usr/local/lib/python3.6/dist-packages/urllib3/connection.py", line 160, in _new_conn
    (self._dns_host, self.port), self.timeout, **extra_kw
  File "/usr/local/lib/python3.6/dist-packages/urllib3/util/connection.py", line 84, in create_connection
    raise err
  File "/usr/local/lib/python3.6/dist-packages/urllib3/util/connection.py", line 74, in create_connection
    sock.connect(sa)
ConnectionRefusedError: [Errno 111] Connection refused

During handling of the above exception, another exception occurred:

Traceback (most recent call last):
  File "/usr/local/lib/python3.6/dist-packages/urllib3/connectionpool.py", line 677, in urlopen
    chunked=chunked,
  File "/usr/local/lib/python3.6/dist-packages/urllib3/connectionpool.py", line 392, in _make_request
    conn.request(method, url, **httplib_request_kw)
  File "/usr/lib/python3.6/http/client.py", line 1264, in request
    self._send_request(method, url, body, headers, encode_chunked)
  File "/usr/lib/python3.6/http/client.py", line 1310, in _send_request
    self.endheaders(body, encode_chunked=encode_chunked)
  File "/usr/lib/python3.6/http/client.py", line 1259, in endheaders
    self._send_output(message_body, encode_chunked=encode_chunked)
  File "/usr/lib/python3.6/http/client.py", line 1038, in _send_output
    self.send(msg)
  File "/usr/lib/python3.6/http/client.py", line 976, in send
    self.connect()
  File "/usr/local/lib/python3.6/dist-packages/urllib3/connection.py", line 187, in connect
    conn = self._new_conn()
  File "/usr/local/lib/python3.6/dist-packages/urllib3/connection.py", line 172, in _new_conn
    self, "Failed to establish a new connection: %s" % e
urllib3.exceptions.NewConnectionError: <urllib3.connection.HTTPConnection object at 0x7f860bf90a58>: Failed to establish a new connection: [Errno 111] Connection refused

During handling of the above exception, another exception occurred:

Traceback (most recent call last):
  File "/usr/local/lib/python3.6/dist-packages/requests/adapters.py", line 449, in send
    timeout=timeout
  File "/usr/local/lib/python3.6/dist-packages/urllib3/connectionpool.py", line 725, in urlopen
    method, url, error=e, _pool=self, _stacktrace=sys.exc_info()[2]
  File "/usr/local/lib/python3.6/dist-packages/urllib3/util/retry.py", line 439, in increment
    raise MaxRetryError(_pool, url, error or ResponseError(cause))
urllib3.exceptions.MaxRetryError: HTTPConnectionPool(host='oj-backend', port=8000): Max retries exceeded with url: /api/judge_server_heartbeat/ (Caused by NewConnectionError('<urllib3.connection.HTTPConnection object at 0x7f860bf90a58>: Failed to establish a new connection: [Errno 111] Connection refused',))

During handling of the above exception, another exception occurred:

Traceback (most recent call last):
  File "/code/service.py", line 19, in _request
    "Content-Type": "application/json"}, timeout=5).text
  File "/usr/local/lib/python3.6/dist-packages/requests/api.py", line 119, in post
    return request('post', url, data=data, json=json, **kwargs)
  File "/usr/local/lib/python3.6/dist-packages/requests/api.py", line 61, in request
    return session.request(method=method, url=url, **kwargs)
  File "/usr/local/lib/python3.6/dist-packages/requests/sessions.py", line 530, in request
    resp = self.send(prep, **send_kwargs)
  File "/usr/local/lib/python3.6/dist-packages/requests/sessions.py", line 643, in send
    r = adapter.send(request, **kwargs)
  File "/usr/local/lib/python3.6/dist-packages/requests/adapters.py", line 516, in send
    raise ConnectionError(e, request=request)
requests.exceptions.ConnectionError: HTTPConnectionPool(host='oj-backend', port=8000): Max retries exceeded with url: /api/judge_server_heartbeat/ (Caused by NewConnectionError('<urllib3.connection.HTTPConnection object at 0x7f860bf90a58>: Failed to establish a new connection: [Errno 111] Connection refused',))

During handling of the above exception, another exception occurred:

Traceback (most recent call last):
  File "/code/service.py", line 42, in <module>
    service.heartbeat()
  File "/code/service.py", line 35, in heartbeat
    self._request(data)
  File "/code/service.py", line 22, in _request
    raise JudgeServiceError("Heartbeat request failed")
exception.JudgeServiceError
2021-06-28 04:01:27,050 ERROR HTTPConnectionPool(host='oj-backend', port=8000): Max retries exceeded with url: /api/judge_server_heartbeat/ (Caused by NewConnectionError('<urllib3.connection.HTTPConnection object at 0x7f44fa0aea58>: Failed to establish a new connection: [Errno 111] Connection refused',))
Traceback (most recent call last):
  File "/usr/local/lib/python3.6/dist-packages/urllib3/connection.py", line 160, in _new_conn
    (self._dns_host, self.port), self.timeout, **extra_kw
  File "/usr/local/lib/python3.6/dist-packages/urllib3/util/connection.py", line 84, in create_connection
    raise err
  File "/usr/local/lib/python3.6/dist-packages/urllib3/util/connection.py", line 74, in create_connection
    sock.connect(sa)
ConnectionRefusedError: [Errno 111] Connection refused

During handling of the above exception, another exception occurred:

Traceback (most recent call last):
  File "/usr/local/lib/python3.6/dist-packages/urllib3/connectionpool.py", line 677, in urlopen
    chunked=chunked,
  File "/usr/local/lib/python3.6/dist-packages/urllib3/connectionpool.py", line 392, in _make_request
    conn.request(method, url, **httplib_request_kw)
  File "/usr/lib/python3.6/http/client.py", line 1264, in request
    self._send_request(method, url, body, headers, encode_chunked)
  File "/usr/lib/python3.6/http/client.py", line 1310, in _send_request
    self.endheaders(body, encode_chunked=encode_chunked)
  File "/usr/lib/python3.6/http/client.py", line 1259, in endheaders
    self._send_output(message_body, encode_chunked=encode_chunked)
  File "/usr/lib/python3.6/http/client.py", line 1038, in _send_output
    self.send(msg)
  File "/usr/lib/python3.6/http/client.py", line 976, in send
    self.connect()
  File "/usr/local/lib/python3.6/dist-packages/urllib3/connection.py", line 187, in connect
    conn = self._new_conn()
  File "/usr/local/lib/python3.6/dist-packages/urllib3/connection.py", line 172, in _new_conn
    self, "Failed to establish a new connection: %s" % e
urllib3.exceptions.NewConnectionError: <urllib3.connection.HTTPConnection object at 0x7f44fa0aea58>: Failed to establish a new connection: [Errno 111] Connection refused

During handling of the above exception, another exception occurred:

Traceback (most recent call last):
  File "/usr/local/lib/python3.6/dist-packages/requests/adapters.py", line 449, in send
    timeout=timeout
  File "/usr/local/lib/python3.6/dist-packages/urllib3/connectionpool.py", line 725, in urlopen
    method, url, error=e, _pool=self, _stacktrace=sys.exc_info()[2]
  File "/usr/local/lib/python3.6/dist-packages/urllib3/util/retry.py", line 439, in increment
    raise MaxRetryError(_pool, url, error or ResponseError(cause))
urllib3.exceptions.MaxRetryError: HTTPConnectionPool(host='oj-backend', port=8000): Max retries exceeded with url: /api/judge_server_heartbeat/ (Caused by NewConnectionError('<urllib3.connection.HTTPConnection object at 0x7f44fa0aea58>: Failed to establish a new connection: [Errno 111] Connection refused',))

During handling of the above exception, another exception occurred:

Traceback (most recent call last):
  File "/code/service.py", line 19, in _request
    "Content-Type": "application/json"}, timeout=5).text
  File "/usr/local/lib/python3.6/dist-packages/requests/api.py", line 119, in post
    return request('post', url, data=data, json=json, **kwargs)
  File "/usr/local/lib/python3.6/dist-packages/requests/api.py", line 61, in request
    return session.request(method=method, url=url, **kwargs)
  File "/usr/local/lib/python3.6/dist-packages/requests/sessions.py", line 530, in request
    resp = self.send(prep, **send_kwargs)
  File "/usr/local/lib/python3.6/dist-packages/requests/sessions.py", line 643, in send
    r = adapter.send(request, **kwargs)
  File "/usr/local/lib/python3.6/dist-packages/requests/adapters.py", line 516, in send
    raise ConnectionError(e, request=request)
requests.exceptions.ConnectionError: HTTPConnectionPool(host='oj-backend', port=8000): Max retries exceeded with url: /api/judge_server_heartbeat/ (Caused by NewConnectionError('<urllib3.connection.HTTPConnection object at 0x7f44fa0aea58>: Failed to establish a new connection: [Errno 111] Connection refused',))
2021-06-28 04:01:27,055 ERROR 
Traceback (most recent call last):
  File "/usr/local/lib/python3.6/dist-packages/urllib3/connection.py", line 160, in _new_conn
    (self._dns_host, self.port), self.timeout, **extra_kw
  File "/usr/local/lib/python3.6/dist-packages/urllib3/util/connection.py", line 84, in create_connection
    raise err
  File "/usr/local/lib/python3.6/dist-packages/urllib3/util/connection.py", line 74, in create_connection
    sock.connect(sa)
ConnectionRefusedError: [Errno 111] Connection refused

During handling of the above exception, another exception occurred:

Traceback (most recent call last):
  File "/usr/local/lib/python3.6/dist-packages/urllib3/connectionpool.py", line 677, in urlopen
    chunked=chunked,
  File "/usr/local/lib/python3.6/dist-packages/urllib3/connectionpool.py", line 392, in _make_request
    conn.request(method, url, **httplib_request_kw)
  File "/usr/lib/python3.6/http/client.py", line 1264, in request
    self._send_request(method, url, body, headers, encode_chunked)
  File "/usr/lib/python3.6/http/client.py", line 1310, in _send_request
    self.endheaders(body, encode_chunked=encode_chunked)
  File "/usr/lib/python3.6/http/client.py", line 1259, in endheaders
    self._send_output(message_body, encode_chunked=encode_chunked)
  File "/usr/lib/python3.6/http/client.py", line 1038, in _send_output
    self.send(msg)
  File "/usr/lib/python3.6/http/client.py", line 976, in send
    self.connect()
  File "/usr/local/lib/python3.6/dist-packages/urllib3/connection.py", line 187, in connect
    conn = self._new_conn()
  File "/usr/local/lib/python3.6/dist-packages/urllib3/connection.py", line 172, in _new_conn
    self, "Failed to establish a new connection: %s" % e
urllib3.exceptions.NewConnectionError: <urllib3.connection.HTTPConnection object at 0x7f44fa0aea58>: Failed to establish a new connection: [Errno 111] Connection refused

During handling of the above exception, another exception occurred:

Traceback (most recent call last):
  File "/usr/local/lib/python3.6/dist-packages/requests/adapters.py", line 449, in send
    timeout=timeout
  File "/usr/local/lib/python3.6/dist-packages/urllib3/connectionpool.py", line 725, in urlopen
    method, url, error=e, _pool=self, _stacktrace=sys.exc_info()[2]
  File "/usr/local/lib/python3.6/dist-packages/urllib3/util/retry.py", line 439, in increment
    raise MaxRetryError(_pool, url, error or ResponseError(cause))
urllib3.exceptions.MaxRetryError: HTTPConnectionPool(host='oj-backend', port=8000): Max retries exceeded with url: /api/judge_server_heartbeat/ (Caused by NewConnectionError('<urllib3.connection.HTTPConnection object at 0x7f44fa0aea58>: Failed to establish a new connection: [Errno 111] Connection refused',))

During handling of the above exception, another exception occurred:

Traceback (most recent call last):
  File "/code/service.py", line 19, in _request
    "Content-Type": "application/json"}, timeout=5).text
  File "/usr/local/lib/python3.6/dist-packages/requests/api.py", line 119, in post
    return request('post', url, data=data, json=json, **kwargs)
  File "/usr/local/lib/python3.6/dist-packages/requests/api.py", line 61, in request
    return session.request(method=method, url=url, **kwargs)
  File "/usr/local/lib/python3.6/dist-packages/requests/sessions.py", line 530, in request
    resp = self.send(prep, **send_kwargs)
  File "/usr/local/lib/python3.6/dist-packages/requests/sessions.py", line 643, in send
    r = adapter.send(request, **kwargs)
  File "/usr/local/lib/python3.6/dist-packages/requests/adapters.py", line 516, in send
    raise ConnectionError(e, request=request)
requests.exceptions.ConnectionError: HTTPConnectionPool(host='oj-backend', port=8000): Max retries exceeded with url: /api/judge_server_heartbeat/ (Caused by NewConnectionError('<urllib3.connection.HTTPConnection object at 0x7f44fa0aea58>: Failed to establish a new connection: [Errno 111] Connection refused',))

During handling of the above exception, another exception occurred:

Traceback (most recent call last):
  File "/code/service.py", line 42, in <module>
    service.heartbeat()
  File "/code/service.py", line 35, in heartbeat
    self._request(data)
  File "/code/service.py", line 22, in _request
    raise JudgeServiceError("Heartbeat request failed")
exception.JudgeServiceError
2021-06-28 04:01:34,089 ERROR HTTPConnectionPool(host='oj-backend', port=8000): Max retries exceeded with url: /api/judge_server_heartbeat/ (Caused by NewConnectionError('<urllib3.connection.HTTPConnection object at 0x7f7effb2ba58>: Failed to establish a new connection: [Errno 111] Connection refused',))
Traceback (most recent call last):
  File "/usr/local/lib/python3.6/dist-packages/urllib3/connection.py", line 160, in _new_conn
    (self._dns_host, self.port), self.timeout, **extra_kw
  File "/usr/local/lib/python3.6/dist-packages/urllib3/util/connection.py", line 84, in create_connection
    raise err
  File "/usr/local/lib/python3.6/dist-packages/urllib3/util/connection.py", line 74, in create_connection
    sock.connect(sa)
ConnectionRefusedError: [Errno 111] Connection refused

During handling of the above exception, another exception occurred:

Traceback (most recent call last):
  File "/usr/local/lib/python3.6/dist-packages/urllib3/connectionpool.py", line 677, in urlopen
    chunked=chunked,
  File "/usr/local/lib/python3.6/dist-packages/urllib3/connectionpool.py", line 392, in _make_request
    conn.request(method, url, **httplib_request_kw)
  File "/usr/lib/python3.6/http/client.py", line 1264, in request
    self._send_request(method, url, body, headers, encode_chunked)
  File "/usr/lib/python3.6/http/client.py", line 1310, in _send_request
    self.endheaders(body, encode_chunked=encode_chunked)
  File "/usr/lib/python3.6/http/client.py", line 1259, in endheaders
    self._send_output(message_body, encode_chunked=encode_chunked)
  File "/usr/lib/python3.6/http/client.py", line 1038, in _send_output
    self.send(msg)
  File "/usr/lib/python3.6/http/client.py", line 976, in send
    self.connect()
  File "/usr/local/lib/python3.6/dist-packages/urllib3/connection.py", line 187, in connect
    conn = self._new_conn()
  File "/usr/local/lib/python3.6/dist-packages/urllib3/connection.py", line 172, in _new_conn
    self, "Failed to establish a new connection: %s" % e
urllib3.exceptions.NewConnectionError: <urllib3.connection.HTTPConnection object at 0x7f7effb2ba58>: Failed to establish a new connection: [Errno 111] Connection refused

During handling of the above exception, another exception occurred:

Traceback (most recent call last):
  File "/usr/local/lib/python3.6/dist-packages/requests/adapters.py", line 449, in send
    timeout=timeout
  File "/usr/local/lib/python3.6/dist-packages/urllib3/connectionpool.py", line 725, in urlopen
    method, url, error=e, _pool=self, _stacktrace=sys.exc_info()[2]
  File "/usr/local/lib/python3.6/dist-packages/urllib3/util/retry.py", line 439, in increment
    raise MaxRetryError(_pool, url, error or ResponseError(cause))
urllib3.exceptions.MaxRetryError: HTTPConnectionPool(host='oj-backend', port=8000): Max retries exceeded with url: /api/judge_server_heartbeat/ (Caused by NewConnectionError('<urllib3.connection.HTTPConnection object at 0x7f7effb2ba58>: Failed to establish a new connection: [Errno 111] Connection refused',))

During handling of the above exception, another exception occurred:

Traceback (most recent call last):
  File "/code/service.py", line 19, in _request
    "Content-Type": "application/json"}, timeout=5).text
  File "/usr/local/lib/python3.6/dist-packages/requests/api.py", line 119, in post
    return request('post', url, data=data, json=json, **kwargs)
  File "/usr/local/lib/python3.6/dist-packages/requests/api.py", line 61, in request
    return session.request(method=method, url=url, **kwargs)
  File "/usr/local/lib/python3.6/dist-packages/requests/sessions.py", line 530, in request
    resp = self.send(prep, **send_kwargs)
  File "/usr/local/lib/python3.6/dist-packages/requests/sessions.py", line 643, in send
    r = adapter.send(request, **kwargs)
  File "/usr/local/lib/python3.6/dist-packages/requests/adapters.py", line 516, in send
    raise ConnectionError(e, request=request)
requests.exceptions.ConnectionError: HTTPConnectionPool(host='oj-backend', port=8000): Max retries exceeded with url: /api/judge_server_heartbeat/ (Caused by NewConnectionError('<urllib3.connection.HTTPConnection object at 0x7f7effb2ba58>: Failed to establish a new connection: [Errno 111] Connection refused',))
2021-06-28 04:01:34,106 ERROR 
Traceback (most recent call last):
  File "/usr/local/lib/python3.6/dist-packages/urllib3/connection.py", line 160, in _new_conn
    (self._dns_host, self.port), self.timeout, **extra_kw
  File "/usr/local/lib/python3.6/dist-packages/urllib3/util/connection.py", line 84, in create_connection
    raise err
  File "/usr/local/lib/python3.6/dist-packages/urllib3/util/connection.py", line 74, in create_connection
    sock.connect(sa)
ConnectionRefusedError: [Errno 111] Connection refused

During handling of the above exception, another exception occurred:

Traceback (most recent call last):
  File "/usr/local/lib/python3.6/dist-packages/urllib3/connectionpool.py", line 677, in urlopen
    chunked=chunked,
  File "/usr/local/lib/python3.6/dist-packages/urllib3/connectionpool.py", line 392, in _make_request
    conn.request(method, url, **httplib_request_kw)
  File "/usr/lib/python3.6/http/client.py", line 1264, in request
    self._send_request(method, url, body, headers, encode_chunked)
  File "/usr/lib/python3.6/http/client.py", line 1310, in _send_request
    self.endheaders(body, encode_chunked=encode_chunked)
  File "/usr/lib/python3.6/http/client.py", line 1259, in endheaders
    self._send_output(message_body, encode_chunked=encode_chunked)
  File "/usr/lib/python3.6/http/client.py", line 1038, in _send_output
    self.send(msg)
  File "/usr/lib/python3.6/http/client.py", line 976, in send
    self.connect()
  File "/usr/local/lib/python3.6/dist-packages/urllib3/connection.py", line 187, in connect
    conn = self._new_conn()
  File "/usr/local/lib/python3.6/dist-packages/urllib3/connection.py", line 172, in _new_conn
    self, "Failed to establish a new connection: %s" % e
urllib3.exceptions.NewConnectionError: <urllib3.connection.HTTPConnection object at 0x7f7effb2ba58>: Failed to establish a new connection: [Errno 111] Connection refused

During handling of the above exception, another exception occurred:

Traceback (most recent call last):
  File "/usr/local/lib/python3.6/dist-packages/requests/adapters.py", line 449, in send
    timeout=timeout
  File "/usr/local/lib/python3.6/dist-packages/urllib3/connectionpool.py", line 725, in urlopen
    method, url, error=e, _pool=self, _stacktrace=sys.exc_info()[2]
  File "/usr/local/lib/python3.6/dist-packages/urllib3/util/retry.py", line 439, in increment
    raise MaxRetryError(_pool, url, error or ResponseError(cause))
urllib3.exceptions.MaxRetryError: HTTPConnectionPool(host='oj-backend', port=8000): Max retries exceeded with url: /api/judge_server_heartbeat/ (Caused by NewConnectionError('<urllib3.connection.HTTPConnection object at 0x7f7effb2ba58>: Failed to establish a new connection: [Errno 111] Connection refused',))

During handling of the above exception, another exception occurred:

Traceback (most recent call last):
  File "/code/service.py", line 19, in _request
    "Content-Type": "application/json"}, timeout=5).text
  File "/usr/local/lib/python3.6/dist-packages/requests/api.py", line 119, in post
    return request('post', url, data=data, json=json, **kwargs)
  File "/usr/local/lib/python3.6/dist-packages/requests/api.py", line 61, in request
    return session.request(method=method, url=url, **kwargs)
  File "/usr/local/lib/python3.6/dist-packages/requests/sessions.py", line 530, in request
    resp = self.send(prep, **send_kwargs)
  File "/usr/local/lib/python3.6/dist-packages/requests/sessions.py", line 643, in send
    r = adapter.send(request, **kwargs)
  File "/usr/local/lib/python3.6/dist-packages/requests/adapters.py", line 516, in send
    raise ConnectionError(e, request=request)
requests.exceptions.ConnectionError: HTTPConnectionPool(host='oj-backend', port=8000): Max retries exceeded with url: /api/judge_server_heartbeat/ (Caused by NewConnectionError('<urllib3.connection.HTTPConnection object at 0x7f7effb2ba58>: Failed to establish a new connection: [Errno 111] Connection refused',))

During handling of the above exception, another exception occurred:

Traceback (most recent call last):
  File "/code/service.py", line 42, in <module>
    service.heartbeat()
  File "/code/service.py", line 35, in heartbeat
    self._request(data)
  File "/code/service.py", line 22, in _request
    raise JudgeServiceError("Heartbeat request failed")
exception.JudgeServiceError
2021-06-28 04:01:40,116 ERROR HTTPConnectionPool(host='oj-backend', port=8000): Max retries exceeded with url: /api/judge_server_heartbeat/ (Caused by NewConnectionError('<urllib3.connection.HTTPConnection object at 0x7f10973c7a58>: Failed to establish a new connection: [Errno 111] Connection refused',))
Traceback (most recent call last):
  File "/usr/local/lib/python3.6/dist-packages/urllib3/connection.py", line 160, in _new_conn
    (self._dns_host, self.port), self.timeout, **extra_kw
  File "/usr/local/lib/python3.6/dist-packages/urllib3/util/connection.py", line 84, in create_connection
    raise err
  File "/usr/local/lib/python3.6/dist-packages/urllib3/util/connection.py", line 74, in create_connection
    sock.connect(sa)
ConnectionRefusedError: [Errno 111] Connection refused

During handling of the above exception, another exception occurred:

Traceback (most recent call last):
  File "/usr/local/lib/python3.6/dist-packages/urllib3/connectionpool.py", line 677, in urlopen
    chunked=chunked,
  File "/usr/local/lib/python3.6/dist-packages/urllib3/connectionpool.py", line 392, in _make_request
    conn.request(method, url, **httplib_request_kw)
  File "/usr/lib/python3.6/http/client.py", line 1264, in request
    self._send_request(method, url, body, headers, encode_chunked)
  File "/usr/lib/python3.6/http/client.py", line 1310, in _send_request
    self.endheaders(body, encode_chunked=encode_chunked)
  File "/usr/lib/python3.6/http/client.py", line 1259, in endheaders
    self._send_output(message_body, encode_chunked=encode_chunked)
  File "/usr/lib/python3.6/http/client.py", line 1038, in _send_output
    self.send(msg)
  File "/usr/lib/python3.6/http/client.py", line 976, in send
    self.connect()
  File "/usr/local/lib/python3.6/dist-packages/urllib3/connection.py", line 187, in connect
    conn = self._new_conn()
  File "/usr/local/lib/python3.6/dist-packages/urllib3/connection.py", line 172, in _new_conn
    self, "Failed to establish a new connection: %s" % e
urllib3.exceptions.NewConnectionError: <urllib3.connection.HTTPConnection object at 0x7f10973c7a58>: Failed to establish a new connection: [Errno 111] Connection refused

During handling of the above exception, another exception occurred:

Traceback (most recent call last):
  File "/usr/local/lib/python3.6/dist-packages/requests/adapters.py", line 449, in send
    timeout=timeout
  File "/usr/local/lib/python3.6/dist-packages/urllib3/connectionpool.py", line 725, in urlopen
    method, url, error=e, _pool=self, _stacktrace=sys.exc_info()[2]
  File "/usr/local/lib/python3.6/dist-packages/urllib3/util/retry.py", line 439, in increment
    raise MaxRetryError(_pool, url, error or ResponseError(cause))
urllib3.exceptions.MaxRetryError: HTTPConnectionPool(host='oj-backend', port=8000): Max retries exceeded with url: /api/judge_server_heartbeat/ (Caused by NewConnectionError('<urllib3.connection.HTTPConnection object at 0x7f10973c7a58>: Failed to establish a new connection: [Errno 111] Connection refused',))

During handling of the above exception, another exception occurred:

Traceback (most recent call last):
  File "/code/service.py", line 19, in _request
    "Content-Type": "application/json"}, timeout=5).text
  File "/usr/local/lib/python3.6/dist-packages/requests/api.py", line 119, in post
    return request('post', url, data=data, json=json, **kwargs)
  File "/usr/local/lib/python3.6/dist-packages/requests/api.py", line 61, in request
    return session.request(method=method, url=url, **kwargs)
  File "/usr/local/lib/python3.6/dist-packages/requests/sessions.py", line 530, in request
    resp = self.send(prep, **send_kwargs)
  File "/usr/local/lib/python3.6/dist-packages/requests/sessions.py", line 643, in send
    r = adapter.send(request, **kwargs)
  File "/usr/local/lib/python3.6/dist-packages/requests/adapters.py", line 516, in send
    raise ConnectionError(e, request=request)
requests.exceptions.ConnectionError: HTTPConnectionPool(host='oj-backend', port=8000): Max retries exceeded with url: /api/judge_server_heartbeat/ (Caused by NewConnectionError('<urllib3.connection.HTTPConnection object at 0x7f10973c7a58>: Failed to establish a new connection: [Errno 111] Connection refused',))
2021-06-28 04:01:40,120 ERROR 
Traceback (most recent call last):
  File "/usr/local/lib/python3.6/dist-packages/urllib3/connection.py", line 160, in _new_conn
    (self._dns_host, self.port), self.timeout, **extra_kw
  File "/usr/local/lib/python3.6/dist-packages/urllib3/util/connection.py", line 84, in create_connection
    raise err
  File "/usr/local/lib/python3.6/dist-packages/urllib3/util/connection.py", line 74, in create_connection
    sock.connect(sa)
ConnectionRefusedError: [Errno 111] Connection refused

During handling of the above exception, another exception occurred:

Traceback (most recent call last):
  File "/usr/local/lib/python3.6/dist-packages/urllib3/connectionpool.py", line 677, in urlopen
    chunked=chunked,
  File "/usr/local/lib/python3.6/dist-packages/urllib3/connectionpool.py", line 392, in _make_request
    conn.request(method, url, **httplib_request_kw)
  File "/usr/lib/python3.6/http/client.py", line 1264, in request
    self._send_request(method, url, body, headers, encode_chunked)
  File "/usr/lib/python3.6/http/client.py", line 1310, in _send_request
    self.endheaders(body, encode_chunked=encode_chunked)
  File "/usr/lib/python3.6/http/client.py", line 1259, in endheaders
    self._send_output(message_body, encode_chunked=encode_chunked)
  File "/usr/lib/python3.6/http/client.py", line 1038, in _send_output
    self.send(msg)
  File "/usr/lib/python3.6/http/client.py", line 976, in send
    self.connect()
  File "/usr/local/lib/python3.6/dist-packages/urllib3/connection.py", line 187, in connect
    conn = self._new_conn()
  File "/usr/local/lib/python3.6/dist-packages/urllib3/connection.py", line 172, in _new_conn
    self, "Failed to establish a new connection: %s" % e
urllib3.exceptions.NewConnectionError: <urllib3.connection.HTTPConnection object at 0x7f10973c7a58>: Failed to establish a new connection: [Errno 111] Connection refused

During handling of the above exception, another exception occurred:

Traceback (most recent call last):
  File "/usr/local/lib/python3.6/dist-packages/requests/adapters.py", line 449, in send
    timeout=timeout
  File "/usr/local/lib/python3.6/dist-packages/urllib3/connectionpool.py", line 725, in urlopen
    method, url, error=e, _pool=self, _stacktrace=sys.exc_info()[2]
  File "/usr/local/lib/python3.6/dist-packages/urllib3/util/retry.py", line 439, in increment
    raise MaxRetryError(_pool, url, error or ResponseError(cause))
urllib3.exceptions.MaxRetryError: HTTPConnectionPool(host='oj-backend', port=8000): Max retries exceeded with url: /api/judge_server_heartbeat/ (Caused by NewConnectionError('<urllib3.connection.HTTPConnection object at 0x7f10973c7a58>: Failed to establish a new connection: [Errno 111] Connection refused',))

During handling of the above exception, another exception occurred:

Traceback (most recent call last):
  File "/code/service.py", line 19, in _request
    "Content-Type": "application/json"}, timeout=5).text
  File "/usr/local/lib/python3.6/dist-packages/requests/api.py", line 119, in post
    return request('post', url, data=data, json=json, **kwargs)
  File "/usr/local/lib/python3.6/dist-packages/requests/api.py", line 61, in request
    return session.request(method=method, url=url, **kwargs)
  File "/usr/local/lib/python3.6/dist-packages/requests/sessions.py", line 530, in request
    resp = self.send(prep, **send_kwargs)
  File "/usr/local/lib/python3.6/dist-packages/requests/sessions.py", line 643, in send
    r = adapter.send(request, **kwargs)
  File "/usr/local/lib/python3.6/dist-packages/requests/adapters.py", line 516, in send
    raise ConnectionError(e, request=request)
requests.exceptions.ConnectionError: HTTPConnectionPool(host='oj-backend', port=8000): Max retries exceeded with url: /api/judge_server_heartbeat/ (Caused by NewConnectionError('<urllib3.connection.HTTPConnection object at 0x7f10973c7a58>: Failed to establish a new connection: [Errno 111] Connection refused',))

During handling of the above exception, another exception occurred:

Traceback (most recent call last):
  File "/code/service.py", line 42, in <module>
    service.heartbeat()
  File "/code/service.py", line 35, in heartbeat
    self._request(data)
  File "/code/service.py", line 22, in _request
    raise JudgeServiceError("Heartbeat request failed")
exception.JudgeServiceError
2021-06-28 04:01:45,908 ERROR HTTPConnectionPool(host='oj-backend', port=8000): Max retries exceeded with url: /api/judge_server_heartbeat/ (Caused by NewConnectionError('<urllib3.connection.HTTPConnection object at 0x7f6ce5a3fa58>: Failed to establish a new connection: [Errno 111] Connection refused',))
Traceback (most recent call last):
  File "/usr/local/lib/python3.6/dist-packages/urllib3/connection.py", line 160, in _new_conn
    (self._dns_host, self.port), self.timeout, **extra_kw
  File "/usr/local/lib/python3.6/dist-packages/urllib3/util/connection.py", line 84, in create_connection
    raise err
  File "/usr/local/lib/python3.6/dist-packages/urllib3/util/connection.py", line 74, in create_connection
    sock.connect(sa)
ConnectionRefusedError: [Errno 111] Connection refused

During handling of the above exception, another exception occurred:

Traceback (most recent call last):
  File "/usr/local/lib/python3.6/dist-packages/urllib3/connectionpool.py", line 677, in urlopen
    chunked=chunked,
  File "/usr/local/lib/python3.6/dist-packages/urllib3/connectionpool.py", line 392, in _make_request
    conn.request(method, url, **httplib_request_kw)
  File "/usr/lib/python3.6/http/client.py", line 1264, in request
    self._send_request(method, url, body, headers, encode_chunked)
  File "/usr/lib/python3.6/http/client.py", line 1310, in _send_request
    self.endheaders(body, encode_chunked=encode_chunked)
  File "/usr/lib/python3.6/http/client.py", line 1259, in endheaders
    self._send_output(message_body, encode_chunked=encode_chunked)
  File "/usr/lib/python3.6/http/client.py", line 1038, in _send_output
    self.send(msg)
  File "/usr/lib/python3.6/http/client.py", line 976, in send
    self.connect()
  File "/usr/local/lib/python3.6/dist-packages/urllib3/connection.py", line 187, in connect
    conn = self._new_conn()
  File "/usr/local/lib/python3.6/dist-packages/urllib3/connection.py", line 172, in _new_conn
    self, "Failed to establish a new connection: %s" % e
urllib3.exceptions.NewConnectionError: <urllib3.connection.HTTPConnection object at 0x7f6ce5a3fa58>: Failed to establish a new connection: [Errno 111] Connection refused

During handling of the above exception, another exception occurred:

Traceback (most recent call last):
  File "/usr/local/lib/python3.6/dist-packages/requests/adapters.py", line 449, in send
    timeout=timeout
  File "/usr/local/lib/python3.6/dist-packages/urllib3/connectionpool.py", line 725, in urlopen
    method, url, error=e, _pool=self, _stacktrace=sys.exc_info()[2]
  File "/usr/local/lib/python3.6/dist-packages/urllib3/util/retry.py", line 439, in increment
    raise MaxRetryError(_pool, url, error or ResponseError(cause))
urllib3.exceptions.MaxRetryError: HTTPConnectionPool(host='oj-backend', port=8000): Max retries exceeded with url: /api/judge_server_heartbeat/ (Caused by NewConnectionError('<urllib3.connection.HTTPConnection object at 0x7f6ce5a3fa58>: Failed to establish a new connection: [Errno 111] Connection refused',))

During handling of the above exception, another exception occurred:

Traceback (most recent call last):
  File "/code/service.py", line 19, in _request
    "Content-Type": "application/json"}, timeout=5).text
  File "/usr/local/lib/python3.6/dist-packages/requests/api.py", line 119, in post
    return request('post', url, data=data, json=json, **kwargs)
  File "/usr/local/lib/python3.6/dist-packages/requests/api.py", line 61, in request
    return session.request(method=method, url=url, **kwargs)
  File "/usr/local/lib/python3.6/dist-packages/requests/sessions.py", line 530, in request
    resp = self.send(prep, **send_kwargs)
  File "/usr/local/lib/python3.6/dist-packages/requests/sessions.py", line 643, in send
    r = adapter.send(request, **kwargs)
  File "/usr/local/lib/python3.6/dist-packages/requests/adapters.py", line 516, in send
    raise ConnectionError(e, request=request)
requests.exceptions.ConnectionError: HTTPConnectionPool(host='oj-backend', port=8000): Max retries exceeded with url: /api/judge_server_heartbeat/ (Caused by NewConnectionError('<urllib3.connection.HTTPConnection object at 0x7f6ce5a3fa58>: Failed to establish a new connection: [Errno 111] Connection refused',))
2021-06-28 04:01:45,911 ERROR 
Traceback (most recent call last):
  File "/usr/local/lib/python3.6/dist-packages/urllib3/connection.py", line 160, in _new_conn
    (self._dns_host, self.port), self.timeout, **extra_kw
  File "/usr/local/lib/python3.6/dist-packages/urllib3/util/connection.py", line 84, in create_connection
    raise err
  File "/usr/local/lib/python3.6/dist-packages/urllib3/util/connection.py", line 74, in create_connection
    sock.connect(sa)
ConnectionRefusedError: [Errno 111] Connection refused

During handling of the above exception, another exception occurred:

Traceback (most recent call last):
  File "/usr/local/lib/python3.6/dist-packages/urllib3/connectionpool.py", line 677, in urlopen
    chunked=chunked,
  File "/usr/local/lib/python3.6/dist-packages/urllib3/connectionpool.py", line 392, in _make_request
    conn.request(method, url, **httplib_request_kw)
  File "/usr/lib/python3.6/http/client.py", line 1264, in request
    self._send_request(method, url, body, headers, encode_chunked)
  File "/usr/lib/python3.6/http/client.py", line 1310, in _send_request
    self.endheaders(body, encode_chunked=encode_chunked)
  File "/usr/lib/python3.6/http/client.py", line 1259, in endheaders
    self._send_output(message_body, encode_chunked=encode_chunked)
  File "/usr/lib/python3.6/http/client.py", line 1038, in _send_output
    self.send(msg)
  File "/usr/lib/python3.6/http/client.py", line 976, in send
    self.connect()
  File "/usr/local/lib/python3.6/dist-packages/urllib3/connection.py", line 187, in connect
    conn = self._new_conn()
  File "/usr/local/lib/python3.6/dist-packages/urllib3/connection.py", line 172, in _new_conn
    self, "Failed to establish a new connection: %s" % e
urllib3.exceptions.NewConnectionError: <urllib3.connection.HTTPConnection object at 0x7f6ce5a3fa58>: Failed to establish a new connection: [Errno 111] Connection refused

During handling of the above exception, another exception occurred:

Traceback (most recent call last):
  File "/usr/local/lib/python3.6/dist-packages/requests/adapters.py", line 449, in send
    timeout=timeout
  File "/usr/local/lib/python3.6/dist-packages/urllib3/connectionpool.py", line 725, in urlopen
    method, url, error=e, _pool=self, _stacktrace=sys.exc_info()[2]
  File "/usr/local/lib/python3.6/dist-packages/urllib3/util/retry.py", line 439, in increment
    raise MaxRetryError(_pool, url, error or ResponseError(cause))
urllib3.exceptions.MaxRetryError: HTTPConnectionPool(host='oj-backend', port=8000): Max retries exceeded with url: /api/judge_server_heartbeat/ (Caused by NewConnectionError('<urllib3.connection.HTTPConnection object at 0x7f6ce5a3fa58>: Failed to establish a new connection: [Errno 111] Connection refused',))

During handling of the above exception, another exception occurred:

Traceback (most recent call last):
  File "/code/service.py", line 19, in _request
    "Content-Type": "application/json"}, timeout=5).text
  File "/usr/local/lib/python3.6/dist-packages/requests/api.py", line 119, in post
    return request('post', url, data=data, json=json, **kwargs)
  File "/usr/local/lib/python3.6/dist-packages/requests/api.py", line 61, in request
    return session.request(method=method, url=url, **kwargs)
  File "/usr/local/lib/python3.6/dist-packages/requests/sessions.py", line 530, in request
    resp = self.send(prep, **send_kwargs)
  File "/usr/local/lib/python3.6/dist-packages/requests/sessions.py", line 643, in send
    r = adapter.send(request, **kwargs)
  File "/usr/local/lib/python3.6/dist-packages/requests/adapters.py", line 516, in send
    raise ConnectionError(e, request=request)
requests.exceptions.ConnectionError: HTTPConnectionPool(host='oj-backend', port=8000): Max retries exceeded with url: /api/judge_server_heartbeat/ (Caused by NewConnectionError('<urllib3.connection.HTTPConnection object at 0x7f6ce5a3fa58>: Failed to establish a new connection: [Errno 111] Connection refused',))

During handling of the above exception, another exception occurred:

Traceback (most recent call last):
  File "/code/service.py", line 42, in <module>
    service.heartbeat()
  File "/code/service.py", line 35, in heartbeat
    self._request(data)
  File "/code/service.py", line 22, in _request
    raise JudgeServiceError("Heartbeat request failed")
exception.JudgeServiceError
2021-06-28 04:01:51,364 ERROR HTTPConnectionPool(host='oj-backend', port=8000): Max retries exceeded with url: /api/judge_server_heartbeat/ (Caused by NewConnectionError('<urllib3.connection.HTTPConnection object at 0x7f817b367a90>: Failed to establish a new connection: [Errno 111] Connection refused',))
Traceback (most recent call last):
  File "/usr/local/lib/python3.6/dist-packages/urllib3/connection.py", line 160, in _new_conn
    (self._dns_host, self.port), self.timeout, **extra_kw
  File "/usr/local/lib/python3.6/dist-packages/urllib3/util/connection.py", line 84, in create_connection
    raise err
  File "/usr/local/lib/python3.6/dist-packages/urllib3/util/connection.py", line 74, in create_connection
    sock.connect(sa)
ConnectionRefusedError: [Errno 111] Connection refused

During handling of the above exception, another exception occurred:

Traceback (most recent call last):
  File "/usr/local/lib/python3.6/dist-packages/urllib3/connectionpool.py", line 677, in urlopen
    chunked=chunked,
  File "/usr/local/lib/python3.6/dist-packages/urllib3/connectionpool.py", line 392, in _make_request
    conn.request(method, url, **httplib_request_kw)
  File "/usr/lib/python3.6/http/client.py", line 1264, in request
    self._send_request(method, url, body, headers, encode_chunked)
  File "/usr/lib/python3.6/http/client.py", line 1310, in _send_request
    self.endheaders(body, encode_chunked=encode_chunked)
  File "/usr/lib/python3.6/http/client.py", line 1259, in endheaders
    self._send_output(message_body, encode_chunked=encode_chunked)
  File "/usr/lib/python3.6/http/client.py", line 1038, in _send_output
    self.send(msg)
  File "/usr/lib/python3.6/http/client.py", line 976, in send
    self.connect()
  File "/usr/local/lib/python3.6/dist-packages/urllib3/connection.py", line 187, in connect
    conn = self._new_conn()
  File "/usr/local/lib/python3.6/dist-packages/urllib3/connection.py", line 172, in _new_conn
    self, "Failed to establish a new connection: %s" % e
urllib3.exceptions.NewConnectionError: <urllib3.connection.HTTPConnection object at 0x7f817b367a90>: Failed to establish a new connection: [Errno 111] Connection refused

During handling of the above exception, another exception occurred:

Traceback (most recent call last):
  File "/usr/local/lib/python3.6/dist-packages/requests/adapters.py", line 449, in send
    timeout=timeout
  File "/usr/local/lib/python3.6/dist-packages/urllib3/connectionpool.py", line 725, in urlopen
    method, url, error=e, _pool=self, _stacktrace=sys.exc_info()[2]
  File "/usr/local/lib/python3.6/dist-packages/urllib3/util/retry.py", line 439, in increment
    raise MaxRetryError(_pool, url, error or ResponseError(cause))
urllib3.exceptions.MaxRetryError: HTTPConnectionPool(host='oj-backend', port=8000): Max retries exceeded with url: /api/judge_server_heartbeat/ (Caused by NewConnectionError('<urllib3.connection.HTTPConnection object at 0x7f817b367a90>: Failed to establish a new connection: [Errno 111] Connection refused',))

During handling of the above exception, another exception occurred:

Traceback (most recent call last):
  File "/code/service.py", line 19, in _request
    "Content-Type": "application/json"}, timeout=5).text
  File "/usr/local/lib/python3.6/dist-packages/requests/api.py", line 119, in post
    return request('post', url, data=data, json=json, **kwargs)
  File "/usr/local/lib/python3.6/dist-packages/requests/api.py", line 61, in request
    return session.request(method=method, url=url, **kwargs)
  File "/usr/local/lib/python3.6/dist-packages/requests/sessions.py", line 530, in request
    resp = self.send(prep, **send_kwargs)
  File "/usr/local/lib/python3.6/dist-packages/requests/sessions.py", line 643, in send
    r = adapter.send(request, **kwargs)
  File "/usr/local/lib/python3.6/dist-packages/requests/adapters.py", line 516, in send
    raise ConnectionError(e, request=request)
requests.exceptions.ConnectionError: HTTPConnectionPool(host='oj-backend', port=8000): Max retries exceeded with url: /api/judge_server_heartbeat/ (Caused by NewConnectionError('<urllib3.connection.HTTPConnection object at 0x7f817b367a90>: Failed to establish a new connection: [Errno 111] Connection refused',))
2021-06-28 04:01:51,378 ERROR 
Traceback (most recent call last):
  File "/usr/local/lib/python3.6/dist-packages/urllib3/connection.py", line 160, in _new_conn
    (self._dns_host, self.port), self.timeout, **extra_kw
  File "/usr/local/lib/python3.6/dist-packages/urllib3/util/connection.py", line 84, in create_connection
    raise err
  File "/usr/local/lib/python3.6/dist-packages/urllib3/util/connection.py", line 74, in create_connection
    sock.connect(sa)
ConnectionRefusedError: [Errno 111] Connection refused

During handling of the above exception, another exception occurred:

Traceback (most recent call last):
  File "/usr/local/lib/python3.6/dist-packages/urllib3/connectionpool.py", line 677, in urlopen
    chunked=chunked,
  File "/usr/local/lib/python3.6/dist-packages/urllib3/connectionpool.py", line 392, in _make_request
    conn.request(method, url, **httplib_request_kw)
  File "/usr/lib/python3.6/http/client.py", line 1264, in request
    self._send_request(method, url, body, headers, encode_chunked)
  File "/usr/lib/python3.6/http/client.py", line 1310, in _send_request
    self.endheaders(body, encode_chunked=encode_chunked)
  File "/usr/lib/python3.6/http/client.py", line 1259, in endheaders
    self._send_output(message_body, encode_chunked=encode_chunked)
  File "/usr/lib/python3.6/http/client.py", line 1038, in _send_output
    self.send(msg)
  File "/usr/lib/python3.6/http/client.py", line 976, in send
    self.connect()
  File "/usr/local/lib/python3.6/dist-packages/urllib3/connection.py", line 187, in connect
    conn = self._new_conn()
  File "/usr/local/lib/python3.6/dist-packages/urllib3/connection.py", line 172, in _new_conn
    self, "Failed to establish a new connection: %s" % e
urllib3.exceptions.NewConnectionError: <urllib3.connection.HTTPConnection object at 0x7f817b367a90>: Failed to establish a new connection: [Errno 111] Connection refused

During handling of the above exception, another exception occurred:

Traceback (most recent call last):
  File "/usr/local/lib/python3.6/dist-packages/requests/adapters.py", line 449, in send
    timeout=timeout
  File "/usr/local/lib/python3.6/dist-packages/urllib3/connectionpool.py", line 725, in urlopen
    method, url, error=e, _pool=self, _stacktrace=sys.exc_info()[2]
  File "/usr/local/lib/python3.6/dist-packages/urllib3/util/retry.py", line 439, in increment
    raise MaxRetryError(_pool, url, error or ResponseError(cause))
urllib3.exceptions.MaxRetryError: HTTPConnectionPool(host='oj-backend', port=8000): Max retries exceeded with url: /api/judge_server_heartbeat/ (Caused by NewConnectionError('<urllib3.connection.HTTPConnection object at 0x7f817b367a90>: Failed to establish a new connection: [Errno 111] Connection refused',))

During handling of the above exception, another exception occurred:

Traceback (most recent call last):
  File "/code/service.py", line 19, in _request
    "Content-Type": "application/json"}, timeout=5).text
  File "/usr/local/lib/python3.6/dist-packages/requests/api.py", line 119, in post
    return request('post', url, data=data, json=json, **kwargs)
  File "/usr/local/lib/python3.6/dist-packages/requests/api.py", line 61, in request
    return session.request(method=method, url=url, **kwargs)
  File "/usr/local/lib/python3.6/dist-packages/requests/sessions.py", line 530, in request
    resp = self.send(prep, **send_kwargs)
  File "/usr/local/lib/python3.6/dist-packages/requests/sessions.py", line 643, in send
    r = adapter.send(request, **kwargs)
  File "/usr/local/lib/python3.6/dist-packages/requests/adapters.py", line 516, in send
    raise ConnectionError(e, request=request)
requests.exceptions.ConnectionError: HTTPConnectionPool(host='oj-backend', port=8000): Max retries exceeded with url: /api/judge_server_heartbeat/ (Caused by NewConnectionError('<urllib3.connection.HTTPConnection object at 0x7f817b367a90>: Failed to establish a new connection: [Errno 111] Connection refused',))

During handling of the above exception, another exception occurred:

Traceback (most recent call last):
  File "/code/service.py", line 42, in <module>
    service.heartbeat()
  File "/code/service.py", line 35, in heartbeat
    self._request(data)
  File "/code/service.py", line 22, in _request
    raise JudgeServiceError("Heartbeat request failed")
exception.JudgeServiceError
2021-06-28 04:02:46,390 ERROR HTTPConnectionPool(host='oj-backend', port=8000): Max retries exceeded with url: /api/judge_server_heartbeat/ (Caused by NewConnectionError('<urllib3.connection.HTTPConnection object at 0x7f2a0eb28a58>: Failed to establish a new connection: [Errno 111] Connection refused',))
Traceback (most recent call last):
  File "/usr/local/lib/python3.6/dist-packages/urllib3/connection.py", line 160, in _new_conn
    (self._dns_host, self.port), self.timeout, **extra_kw
  File "/usr/local/lib/python3.6/dist-packages/urllib3/util/connection.py", line 84, in create_connection
    raise err
  File "/usr/local/lib/python3.6/dist-packages/urllib3/util/connection.py", line 74, in create_connection
    sock.connect(sa)
ConnectionRefusedError: [Errno 111] Connection refused

During handling of the above exception, another exception occurred:

Traceback (most recent call last):
  File "/usr/local/lib/python3.6/dist-packages/urllib3/connectionpool.py", line 677, in urlopen
    chunked=chunked,
  File "/usr/local/lib/python3.6/dist-packages/urllib3/connectionpool.py", line 392, in _make_request
    conn.request(method, url, **httplib_request_kw)
  File "/usr/lib/python3.6/http/client.py", line 1264, in request
    self._send_request(method, url, body, headers, encode_chunked)
  File "/usr/lib/python3.6/http/client.py", line 1310, in _send_request
    self.endheaders(body, encode_chunked=encode_chunked)
  File "/usr/lib/python3.6/http/client.py", line 1259, in endheaders
    self._send_output(message_body, encode_chunked=encode_chunked)
  File "/usr/lib/python3.6/http/client.py", line 1038, in _send_output
    self.send(msg)
  File "/usr/lib/python3.6/http/client.py", line 976, in send
    self.connect()
  File "/usr/local/lib/python3.6/dist-packages/urllib3/connection.py", line 187, in connect
    conn = self._new_conn()
  File "/usr/local/lib/python3.6/dist-packages/urllib3/connection.py", line 172, in _new_conn
    self, "Failed to establish a new connection: %s" % e
urllib3.exceptions.NewConnectionError: <urllib3.connection.HTTPConnection object at 0x7f2a0eb28a58>: Failed to establish a new connection: [Errno 111] Connection refused

During handling of the above exception, another exception occurred:

Traceback (most recent call last):
  File "/usr/local/lib/python3.6/dist-packages/requests/adapters.py", line 449, in send
    timeout=timeout
  File "/usr/local/lib/python3.6/dist-packages/urllib3/connectionpool.py", line 725, in urlopen
    method, url, error=e, _pool=self, _stacktrace=sys.exc_info()[2]
  File "/usr/local/lib/python3.6/dist-packages/urllib3/util/retry.py", line 439, in increment
    raise MaxRetryError(_pool, url, error or ResponseError(cause))
urllib3.exceptions.MaxRetryError: HTTPConnectionPool(host='oj-backend', port=8000): Max retries exceeded with url: /api/judge_server_heartbeat/ (Caused by NewConnectionError('<urllib3.connection.HTTPConnection object at 0x7f2a0eb28a58>: Failed to establish a new connection: [Errno 111] Connection refused',))

During handling of the above exception, another exception occurred:

Traceback (most recent call last):
  File "/code/service.py", line 19, in _request
    "Content-Type": "application/json"}, timeout=5).text
  File "/usr/local/lib/python3.6/dist-packages/requests/api.py", line 119, in post
    return request('post', url, data=data, json=json, **kwargs)
  File "/usr/local/lib/python3.6/dist-packages/requests/api.py", line 61, in request
    return session.request(method=method, url=url, **kwargs)
  File "/usr/local/lib/python3.6/dist-packages/requests/sessions.py", line 530, in request
    resp = self.send(prep, **send_kwargs)
  File "/usr/local/lib/python3.6/dist-packages/requests/sessions.py", line 643, in send
    r = adapter.send(request, **kwargs)
  File "/usr/local/lib/python3.6/dist-packages/requests/adapters.py", line 516, in send
    raise ConnectionError(e, request=request)
requests.exceptions.ConnectionError: HTTPConnectionPool(host='oj-backend', port=8000): Max retries exceeded with url: /api/judge_server_heartbeat/ (Caused by NewConnectionError('<urllib3.connection.HTTPConnection object at 0x7f2a0eb28a58>: Failed to establish a new connection: [Errno 111] Connection refused',))
2021-06-28 04:02:46,396 ERROR 
Traceback (most recent call last):
  File "/usr/local/lib/python3.6/dist-packages/urllib3/connection.py", line 160, in _new_conn
    (self._dns_host, self.port), self.timeout, **extra_kw
  File "/usr/local/lib/python3.6/dist-packages/urllib3/util/connection.py", line 84, in create_connection
    raise err
  File "/usr/local/lib/python3.6/dist-packages/urllib3/util/connection.py", line 74, in create_connection
    sock.connect(sa)
ConnectionRefusedError: [Errno 111] Connection refused

During handling of the above exception, another exception occurred:

Traceback (most recent call last):
  File "/usr/local/lib/python3.6/dist-packages/urllib3/connectionpool.py", line 677, in urlopen
    chunked=chunked,
  File "/usr/local/lib/python3.6/dist-packages/urllib3/connectionpool.py", line 392, in _make_request
    conn.request(method, url, **httplib_request_kw)
  File "/usr/lib/python3.6/http/client.py", line 1264, in request
    self._send_request(method, url, body, headers, encode_chunked)
  File "/usr/lib/python3.6/http/client.py", line 1310, in _send_request
    self.endheaders(body, encode_chunked=encode_chunked)
  File "/usr/lib/python3.6/http/client.py", line 1259, in endheaders
    self._send_output(message_body, encode_chunked=encode_chunked)
  File "/usr/lib/python3.6/http/client.py", line 1038, in _send_output
    self.send(msg)
  File "/usr/lib/python3.6/http/client.py", line 976, in send
    self.connect()
  File "/usr/local/lib/python3.6/dist-packages/urllib3/connection.py", line 187, in connect
    conn = self._new_conn()
  File "/usr/local/lib/python3.6/dist-packages/urllib3/connection.py", line 172, in _new_conn
    self, "Failed to establish a new connection: %s" % e
urllib3.exceptions.NewConnectionError: <urllib3.connection.HTTPConnection object at 0x7f2a0eb28a58>: Failed to establish a new connection: [Errno 111] Connection refused

During handling of the above exception, another exception occurred:

Traceback (most recent call last):
  File "/usr/local/lib/python3.6/dist-packages/requests/adapters.py", line 449, in send
    timeout=timeout
  File "/usr/local/lib/python3.6/dist-packages/urllib3/connectionpool.py", line 725, in urlopen
    method, url, error=e, _pool=self, _stacktrace=sys.exc_info()[2]
  File "/usr/local/lib/python3.6/dist-packages/urllib3/util/retry.py", line 439, in increment
    raise MaxRetryError(_pool, url, error or ResponseError(cause))
urllib3.exceptions.MaxRetryError: HTTPConnectionPool(host='oj-backend', port=8000): Max retries exceeded with url: /api/judge_server_heartbeat/ (Caused by NewConnectionError('<urllib3.connection.HTTPConnection object at 0x7f2a0eb28a58>: Failed to establish a new connection: [Errno 111] Connection refused',))

During handling of the above exception, another exception occurred:

Traceback (most recent call last):
  File "/code/service.py", line 19, in _request
    "Content-Type": "application/json"}, timeout=5).text
  File "/usr/local/lib/python3.6/dist-packages/requests/api.py", line 119, in post
    return request('post', url, data=data, json=json, **kwargs)
  File "/usr/local/lib/python3.6/dist-packages/requests/api.py", line 61, in request
    return session.request(method=method, url=url, **kwargs)
  File "/usr/local/lib/python3.6/dist-packages/requests/sessions.py", line 530, in request
    resp = self.send(prep, **send_kwargs)
  File "/usr/local/lib/python3.6/dist-packages/requests/sessions.py", line 643, in send
    r = adapter.send(request, **kwargs)
  File "/usr/local/lib/python3.6/dist-packages/requests/adapters.py", line 516, in send
    raise ConnectionError(e, request=request)
requests.exceptions.ConnectionError: HTTPConnectionPool(host='oj-backend', port=8000): Max retries exceeded with url: /api/judge_server_heartbeat/ (Caused by NewConnectionError('<urllib3.connection.HTTPConnection object at 0x7f2a0eb28a58>: Failed to establish a new connection: [Errno 111] Connection refused',))

During handling of the above exception, another exception occurred:

Traceback (most recent call last):
  File "/code/service.py", line 42, in <module>
    service.heartbeat()
  File "/code/service.py", line 35, in heartbeat
    self._request(data)
  File "/code/service.py", line 22, in _request
    raise JudgeServiceError("Heartbeat request failed")
exception.JudgeServiceError
